Workbook

Sheet Main
B2: Ver.#1 | H2: אביזרי פרזול, ידיות ומנעולים | I2: 23 | J2: חברות פעילות בתחום
B4: מוצרים | F4: החברה | G4: ________ | H4: מתוך | J4: חברות במערכת | T4: Website & Service improvement Guide
H5: ככל ששטח המצולע גדול יותר - החברה איכותית יותר. להגדלת התרשים - עמדו עליו: | T5: המלצות לשיפור האתר, השירות והמותג מהות ההמלצות לעדכון הפרמטרים הינה מקסימיזציה יחסית בהשוואה למיטבי מבין כלל אתרי תחום הפעילות ובכך לשדרג את מיקום האתר בדירוג הרייטינג הכולל והיחסי שלו
B6: דירוג הרייטינג היחסי הכולל | G6: > | H6: ככל שהדירוגים בעמודה גבוהים יותר - החברה איכותית יותר | I6: =(I8*H8 + I10*H10 + I12*H12 + I14*H14 + I16*H16 + I18*H18 + I22*H22)/SUM(H8,H10,H12,H14,H16,H18,H20,H22) -> 2.9947638
B8: 1 | C8: מדדים תעריפיים | H8: 1.8 | I8: =I30 -> 4.8051948
B10: 2 | C10: =C76 -> ערכיות רב-שכבתית | H10: 2 | I10: =I76 -> 2.6934762
B12: 3 | C12: =C159 -> גודל ופריסה | H12: 1.8 | I12: =I159 -> 2.4507952
B14: 4 | C14: =C165 -> רמת שירות וממשקים | H14: 1.4 | I14: =I165 -> 0
B16: 5 | C16: =C172 -> אמינות ושקיפות | H16: 1.5 | I16: =I172 -> 3.6
B18: 6 | C18: =C179 -> סייבר ושמירת פרטיות | H18: 1.4 | I18: =I179 -> 3.75
B22: 7 | C22: =C197 -> נוכחות דיגיטלית | H22: 0.6 | I22: =I197 -> 3.9121419
B30: 1 | C30: מדדים תעריפיים (כולל מע"מ) | H30: דירוג משוקלל מנורמל > | I30: =(I32*9+I54+I67)/11 -> 4.8051948 | N30: 1
H31: < | N31: איזור סניף /ים | P31: כן=5 / לא=0
B32: 1 | C32: מדגם מחירים (פריט שאינו נמכר, המחיר=999) | H32: << | I32: =(I33*3+I37*3+I41*3)/9 -> 5 | N32: 1 | O32: צפון | P32: 0
C33: 1.1 | D33: מתקני רשת | H33: < | I33: =(IF(I34=Normalize!G7,5,IF(I34<Normalize!G7,5,IF(I34>Normalize!I7,0,((I34-Normalize!G7)/(Normalize!I7-Normalize!G7))*5)))+IF(I35=Normalize!G8,5,IF(I35<Normalize!G8,5,IF(I35>Normalize!I8,0,5-((I35-Normalize!G8)/(Normalize!I8-Normalize!G8))*5)))+IF(I36=Normalize!G9,5,IF(I36<Normalize!G9,5,IF(I36>Normalize!I9,0,5-((I36-Normalize!G9)/(Normalize!I9-Normalize!G9))*5))))/3 -> 5 | L33: הערות /הבהרות למשתנים | N33: 2 | O33: חיפה והקריות | P33: 0
D34: 1.1.1 | E34: מספר דגמים שונים נמכרים וזמינים במלאי | H34: N | I34: 130 | K34: =D34 -> 1.1.1 | N34: 3 | O34: שרון | P34: 0
D35: 1.1.2 | E35: מחיר מירבי - לא מבצע של הדגם הזול ביותר מבין דגמי המוצר | H35: NV | I35: 60 | K35: =D35 -> 1.1.2 | N35: 4 | O35: מרכז | P35: 0
D36: 1.1.3 | E36: מחיר מירבי - לא מבצע של הדגם היקר ביותר מבין דגמי המוצר | H36: NV | I36: 90 | K36: =D36 -> 1.1.3 | N36: 5 | O36: גוש דן | P36: 5
C37: 1.2 | D37: מערכות הזזה | H37: < | I37: =(IF(I38=Normalize!G11,5,IF(I38<Normalize!G11,5,IF(I38>Normalize!I11,0,((I38-Normalize!G11)/(Normalize!I11-Normalize!G11))*5)))+IF(I39=Normalize!G12,5,IF(I39<Normalize!G12,5,IF(I39>Normalize!I12,0,5-((I39-Normalize!G12)/(Normalize!I12-Normalize!G12))*5)))+IF(I40=Normalize!G13,5,IF(I40<Normalize!G13,5,IF(I40>Normalize!I13,0,5-((I40-Normalize!G13)/(Normalize!I13-Normalize!G13))*5))))/3 -> 5 | N37: 6 | O37: ירושלים | P37: 0
D38: 1.2.1 | E38: מספר דגמים שונים נמכרים וזמינים במלאי | H38: N | I38: 60 | K38: =D38 -> 1.2.1 | N38: 7 | O38: איו"ש | P38: 0
D39: 1.2.2 | E39: מחיר מירבי - לא מבצע של הדגם הזול ביותר מבין דגמי המוצר | H39: NV | I39: 20 | K39: =D39 -> 1.2.2 | N39: 8 | O39: שפלה | P39: 0
D40: 1.2.3 | E40: מחיר מירבי - לא מבצע של הדגם היקר ביותר מבין דגמי המוצר | H40: NV | I40: 30 | K40: =D40 -> 1.2.3 | N40: 9 | O40: דרום | P40: 0
C41: 1.3 | D41: ידיות דלת מעוצבות | H41: < | I41: =(IF(I42=Normalize!G15,5,IF(I42<Normalize!G15,5,IF(I42>Normalize!I15,0,((I42-Normalize!G15)/(Normalize!I15-Normalize!G15))*5)))+IF(I43=Normalize!G16,5,IF(I43<Normalize!G16,5,IF(I43>Normalize!I16,0,5-((I43-Normalize!G16)/(Normalize!I16-Normalize!G16))*5)))+IF(I44=Normalize!G17,5,IF(I44<Normalize!G17,5,IF(I44>Normalize!I17,0,5-((I44-Normalize!G17)/(Normalize!I17-Normalize!G17))*5))))/3 -> 5 | N41: 10 | O41: אילת | P41: 0
D42: 1.3.1 | E42: מספר דגמים שונים נמכרים וזמינים במלאי | H42: N | I42: 5 | K42: =D42 -> 1.3.1 | P42: =SUM(P32:P41)/5 -> 1
D43: 1.3.2 | E43: מחיר מירבי - לא מבצע של הדגם הזול ביותר מבין דגמי המוצר | H43: NV | I43: 8 | K43: =D43 -> 1.3.2
D44: 1.3.3 | E44: מחיר מירבי - לא מבצע של הדגם היקר ביותר מבין דגמי המוצר | H44: NV | I44: 22 | K44: =D44 -> 1.3.3
C45: 1.4 | D45: ידיות מגרה - משיכה | H45: < | I45: =(IF(I46=Normalize!G19,5,IF(I46<Normalize!G19,5,IF(I46>Normalize!I19,0,((I46-Normalize!G19)/(Normalize!I19-Normalize!G19))*5)))+IF(I47=Normalize!G20,5,IF(I47<Normalize!G20,5,IF(I47>Normalize!I20,0,5-((I47-Normalize!G20)/(Normalize!I20-Normalize!G20))*5)))+IF(I48=Normalize!G21,5,IF(I48<Normalize!G21,5,IF(I48>Normalize!I21,0,5-((I48-Normalize!G21)/(Normalize!I21-Normalize!G21))*5))))/3 -> 5
D46: 1.4.1 | E46: מספר דגמים שונים נמכרים וזמינים במלאי | H46: N | I46: 5 | K46: =D46 -> 1.4.1 | N46: 2
D47: 1.4.2 | E47: מחיר מירבי - לא מבצע של הדגם הזול ביותר מבין דגמי המוצר | H47: NV | I47: 8 | K47: =D47 -> 1.4.2 | N47: ישובי סניף /ים /שליחויות /שירות | P47: כן=5 / לא=0 | Q47: איזור
D48: 1.4.3 | E48: מחיר מירבי - לא מבצע של הדגם היקר ביותר מבין דגמי המוצר | H48: NV | I48: 22 | K48: =D48 -> 1.4.3 | N48: 1 | O48: בית שאן | P48: 0 | Q48: צפון
C49: 1.5 | D49: מנעול מגירת משיכה | H49: < | I49: =(IF(I50=Normalize!G23,5,IF(I50<Normalize!G23,5,IF(I50>Normalize!I23,0,((I50-Normalize!G23)/(Normalize!I23-Normalize!G23))*5)))+IF(I51=Normalize!G24,5,IF(I51<Normalize!G24,5,IF(I51>Normalize!I24,0,5-((I51-Normalize!G24)/(Normalize!I24-Normalize!G24))*5)))+IF(I52=Normalize!G25,5,IF(I52<Normalize!G25,5,IF(I52>Normalize!I25,0,5-((I52-Normalize!G25)/(Normalize!I25-Normalize!G25))*5))))/3 -> 5 | N49: 2 | O49: טבריה | P49: 0 | Q49: צפון
D50: 1.5.1 | E50: מספר דגמים שונים נמכרים וזמינים במלאי | H50: N | I50: 5 | K50: =D50 -> 1.5.1 | N50: 3 | O50: טירת כרמל | P50: 0 | Q50: צפון
D51: 1.5.2 | E51: מחיר מירבי - לא מבצע של הדגם הזול ביותר מבין דגמי המוצר | H51: NV | I51: 8 | K51: =D51 -> 1.5.2 | N51: 4 | O51: טמרה | P51: 0 | Q51: צפון
D52: 1.5.3 | E52: מחיר מירבי - לא מבצע של הדגם היקר ביותר מבין דגמי המוצר | H52: NV | I52: 22 | K52: =D52 -> 1.5.3 | N52: 5 | O52: יקנעם עילית | P52: 0 | Q52: צפון
N53: 6 | O53: כרמיאל | P53: 0 | Q53: צפון
B54: 2 | C54: מחירי שירות /משלוח (באיזור העדר שליחות, המחיר=999) | H54: < | I54: =(IF(I55=Normalize!G28,5,IF(I55<Normalize!G28,5,IF(I55>Normalize!I28,0,5-((I55-Normalize!G28)/(Normalize!I28-Normalize!G28))*5)))+ IF(I56=Normalize!G29,5,IF(I56<Normalize!G29,5,IF(I56>Normalize!I29,0,5-((I56-Normalize!G29)/(Normalize!I29-Normalize!G29))*5)))+ IF(I57=Normalize!G30,5,IF(I57<Normalize!G30,5,IF(I57>Normalize!I30,0,5-((I57-Normalize!G30)/(Normalize!I30-Normalize!G30))*5)))+ IF(I58=Normalize!G31,5,IF(I58<Normalize!G31,5,IF(I58>Normalize!I31,0,5-((I58-Normalize!G31)/(Normalize!I31-Normalize!G31))*5)))+ IF(I59=Normalize!G32,5,IF(I59<Normalize!G32,5,IF(I59>Normalize!I32,0,5-((I59-Normalize!G32)/(Normalize!I32-Normalize!G32))*5)))+ IF(I60=Normalize!G33,5,IF(I60<Normalize!G33,5,IF(I60>Normalize!I33,0,5-((I60-Normalize!G33)/(Normalize!I33-Normalize!G33))*5)))+ IF(I61=Normalize!G34,5,IF(I61<Normalize!G34,5,IF(I61>Normalize!I34,0,5-((I61-Normalize!G34)/(Normalize!I34-Normalize!G34))*5)))+ IF(I62=Normalize!G35,5,IF(I62<Normalize!G35,5,IF(I62>Normalize!I35,0,5-((I62-Normalize!G35)/(Normalize!I35-Normalize!G35))*5)))+ IF(I63=Normalize!G36,5,IF(I63<Normalize!G36,5,IF(I63>Normalize!I36,0,5-((I63-Normalize!G36)/(Normalize!I36-Normalize!G36))*5)))+ IF(I64=Normalize!G37,5,IF(I64<Normalize!G37,5,IF(I64>Normalize!I37,0,5-((I64-Normalize!G37)/(Normalize!I37-Normalize!G37))*5)))+ IF(I65=Normalize!G38,5,IF(I65<Normalize!G38,5,IF(I65>Normalize!I38,0,5-((I65-Normalize!G38)/(Normalize!I38-Normalize!G38))*5))))/11 -> 5 | N54: 7 | O54: מגדל העמק | P54: 0 | Q54: צפון
C55: 1.1 | D55: דואר רשום | H55: NV | I55: 35 | K55: =C55 -> 1.1 | N55: 8 | O55: מעלות- תרשיחא | P55: 5 | Q55: צפון
C56: 1.2 | D56: צפון | H56: NV | I56: 125 | K56: =C56 -> 1.2 | N56: 9 | O56: נהריה | P56: 0 | Q56: צפון
C57: 1.3 | D57: חיפה והקריות | H57: NV | I57: 66 | K57: =C57 -> 1.3 | N57: 10 | O57: נוף הגליל | P57: 0 | Q57: צפון | R57: 1
C58: 1.4 | D58: שרון | H58: NV | I58: 200 | K58: =C58 -> 1.4 | N58: 11 | O58: נצרת | P58: 5 | Q58: צפון
...

Sheet Normalize
B2: פרמטרים לנירמול
B4: 1 | C4: מדדים תעריפיים (כולל מע"מ) | G4: MIN | H4: AVR | I4: MAX
B5: 1 | C5: מדגם מחירים (פריט שאינו נמכר, המחיר=999)
C6: 1.1 | D6: מתקני רשת
D7: 1.1.1 | E7: מספר דגמים שונים נמכרים וזמינים במלאי | G7: 130 | H7: =(G7+I7)/2 -> 130 | I7: 130
D8: 1.1.2 | E8: מחיר מירבי - לא מבצע של הדגם הזול ביותר מבין דגמי המוצר | G8: 60 | H8: =(G8+I8)/2 -> 60 | I8: 60
D9: 1.1.3 | E9: מחיר מירבי - לא מבצע של הדגם היקר ביותר מבין דגמי המוצר | G9: 90 | H9: =(G9+I9)/2 -> 90 | I9: 90
C10: 1.2 | D10: מערכות הזזה
D11: 1.2.1 | E11: מספר דגמים שונים נמכרים וזמינים במלאי | G11: 60 | H11: =(G11+I11)/2 -> 60 | I11: 60
D12: 1.2.2 | E12: מחיר מירבי - לא מבצע של הדגם הזול ביותר מבין דגמי המוצר | G12: 20 | H12: =(G12+I12)/2 -> 20 | I12: 20
D13: 1.2.3 | E13: מחיר מירבי - לא מבצע של הדגם היקר ביותר מבין דגמי המוצר | G13: 30 | H13: =(G13+I13)/2 -> 30 | I13: 30
C14: 1.3 | D14: ידיות דלת מעוצבות
D15: 1.3.1 | E15: מספר דגמים שונים נמכרים וזמינים במלאי | G15: 5 | H15: =(G15+I15)/2 -> 5 | I15: 5
D16: 1.3.2 | E16: מחיר מירבי - לא מבצע של הדגם הזול ביותר מבין דגמי המוצר | G16: 8 | H16: =(G16+I16)/2 -> 8 | I16: 8
D17: 1.3.3 | E17: מחיר מירבי - לא מבצע של הדגם היקר ביותר מבין דגמי המוצר | G17: 22 | H17: =(G17+I17)/2 -> 22 | I17: 22
C18: 1.4 | D18: ידיות מגרה - משיכה
D19: 1.4.1 | E19: מספר דגמים שונים נמכרים וזמינים במלאי | G19: 5 | H19: =(G19+I19)/2 -> 5 | I19: 5
D20: 1.4.2 | E20: מחיר מירבי - לא מבצע של הדגם הזול ביותר מבין דגמי המוצר | G20: 8 | H20: =(G20+I20)/2 -> 8 | I20: 8
D21: 1.4.3 | E21: מחיר מירבי - לא מבצע של הדגם היקר ביותר מבין דגמי המוצר | G21: 22 | H21: =(G21+I21)/2 -> 22 | I21: 22
C22: 1.5 | D22: מנעול מגירת משיכה
D23: 1.5.1 | E23: מספר דגמים שונים נמכרים וזמינים במלאי | G23: 5 | H23: =(G23+I23)/2 -> 5 | I23: 5
D24: 1.5.2 | E24: מחיר מירבי - לא מבצע של הדגם הזול ביותר מבין דגמי המוצר | G24: 8 | H24: =(G24+I24)/2 -> 8 | I24: 8
D25: 1.5.3 | E25: מחיר מירבי - לא מבצע של הדגם היקר ביותר מבין דגמי המוצר | G25: 22 | H25: =(G25+I25)/2 -> 22 | I25: 22
B27: 2 | C27: מחירי שירות /משלוח (באיזור העדר שליחות, המחיר=999)
C28: 1.1 | D28: דואר רשום | G28: 35 | H28: =(G28+I28)/2 -> 35 | I28: 35
C29: 1.3 | D29: חיפה והקריות | G29: 125 | H29: =(G29+I29)/2 -> 125 | I29: 125
C30: 1.2 | D30: צפון | G30: 66 | H30: =(G30+I30)/2 -> 66 | I30: 66
C31: 1.4 | D31: שרון | G31: 200 | H31: =(G31+I31)/2 -> 200 | I31: 200
C32: 1.5 | D32: מרכז | G32: 90 | H32: =(G32+I32)/2 -> 90 | I32: 90
C33: 1.6 | D33: גוש-דן | G33: 50 | H33: =(G33+I33)/2 -> 50 | I33: 50
C34: 1.7 | D34: ירושלים | G34: 40 | H34: =(G34+I34)/2 -> 40 | I34: 40
C35: 1.8 | D35: איו"ש | G35: 45 | H35: =(G35+I35)/2 -> 45 | I35: 45
C36: 1.9 | D36: שפלה | G36: 30 | H36: =(G36+I36)/2 -> 30 | I36: 30
C37: 1.10 | D37: דרום | G37: 35 | H37: =(G37+I37)/2 -> 35 | I37: 35
C38: 1.11 | D38: אילת | G38: 200 | H38: =(G38+I38)/2 -> 200 | I38: 200
B40: 2 | C40: ערכיות רב-שכבתית
B41: 2 | C41: מאפייני המוצרים והשירותים
B42: 2 | C42: שירות האונליין | D42: שירות האונליין
D43: 2.2.3 | E43: זמן אספקה מירבי מובטח של הזמנת שליחות (ימי עסקים) | G43: 5 | H43: =(G43+I43)/2 -> 5 | I43: 5
B45: 4 | C45: רמת שירות וממשקים
...
