Workbook

Sheet Main
B2: Ver.#1 | H2: אביזרי מסיבות | I2: 628 | J2: חברות פעילות בתחום
B4: טט | F4: החברה | G4: ________ | H4: מתוך | J4: חברות במערכת | T4: Website & Service improvement Guide
H5: ככל ששטח המצולע גדול יותר - החברה איכותית יותר. להגדלת התרשים - עמדו עליו: | T5: המלצות לשיפור האתר, השירות והמותג מהות ההמלצות לעדכון הפרמטרים הינה מקסימיזציה יחסית בהשוואה למיטבי מבין כלל אתרי תחום הפעילות ובכך לשדרג את מיקום האתר בדירוג הרייטינג הכולל והיחסי שלו
B6: דירוג הרייטינג היחסי הכולל | G6: > | H6: ככל שהדירוגים בעמודה גבוהים יותר - החברה איכותית יותר | I6: =(I8*H8 + I10*H10 + I12*H12 + I14*H14 + I16*H16 + I18*H18 + I22*H22)/SUM(H8,H10,H12,H14,H16,H18,H20,H22) -> 3.1506997
B8: 1 | C8: מדדים תעריפיים | H8: 1.8 | I8: =I30 -> 4.9330357
B10: 2 | C10: =C95 -> ערכיות רב-שכבתית | H10: 2 | I10: =I95 -> 2.9104478
B12: 3 | C12: =C176 -> גודל ופריסה | H12: 1.8 | I12: =I176 -> 2.0192786
B14: 4 | C14: =C181 -> רמת שירות וממשקים | H14: 1.4 | I14: =I181 -> 1.25
B16: 5 | C16: =C188 -> אמינות ושקיפות | H16: 1.5 | I16: =I188 -> 3.6
B18: 6 | C18: =C195 -> סייבר ושמירת פרטיות | H18: 1.4 | I18: =I195 -> 3.75
B22: 7 | C22: =C213 -> נוכחות דיגיטלית | H22: 0.6 | I22: =I213 -> 3.9121419
B30: 1 | C30: מדדים תעריפיים (כולל מע"מ) | H30: דירוג משוקלל מנורמל > | I30: =(I32*30+I74+I86)/32 -> 4.9330357 | N30: 1
N31: איזור סניף /ים | P31: כן=5 / לא=0
B32: 1 | C32: מדגם מחירים (פריט שאינו נמכר, המחיר=999) | H32: << | I32: =(I33*3+I37*3+I41*3+I45*3+I49*3+I53*3+I57*3+I61*3+I65*3+I69*3)/30 -> 5 | N32: 1 | O32: צפון | P32: 0
C33: 1.1 | D33: בלונים | H33: < | I33: =(IF(I34=Normalize!G7,5,IF(I34<Normalize!G7,5,IF(I34>Normalize!I7,0,((I34-Normalize!G7)/(Normalize!I7-Normalize!G7))*5)))+IF(I35=Normalize!G8,5,IF(I35<Normalize!G8,5,IF(I35>Normalize!I8,0,5-((I35-Normalize!G8)/(Normalize!I8-Normalize!G8))*5)))+IF(I36=Normalize!G9,5,IF(I36<Normalize!G9,5,IF(I36>Normalize!I9,0,5-((I36-Normalize!G9)/(Normalize!I9-Normalize!G9))*5))))/3 -> 5 | L33: הערות /הבהרות למשתנים | N33: 2 | O33: חיפה והקריות | P33: 0
D34: 1.1.1 | E34: מספר מחירונים זמינים | H34: N | I34: 130 | K34: =D34 -> 1.1.1 | N34: 3 | O34: שרון | P34: 0
D35: 1.1.2 | E35: מחיר מזערי במחירונים | H35: NV | I35: 60 | K35: =D35 -> 1.1.2 | N35: 4 | O35: מרכז | P35: 0
D36: 1.1.3 | E36: מחיר מירבי במחירונים | H36: NV | I36: 90 | K36: =D36 -> 1.1.3 | N36: 5 | O36: גוש דן | P36: 5
C37: 1.2 | D37: כובעים | H37: < | I37: =(IF(I38=Normalize!G11,5,IF(I38<Normalize!G11,5,IF(I38>Normalize!I11,0,((I38-Normalize!G11)/(Normalize!I11-Normalize!G11))*5)))+IF(I39=Normalize!G12,5,IF(I39<Normalize!G12,5,IF(I39>Normalize!I12,0,5-((I39-Normalize!G12)/(Normalize!I12-Normalize!G12))*5)))+IF(I40=Normalize!G13,5,IF(I40<Normalize!G13,5,IF(I40>Normalize!I13,0,5-((I40-Normalize!G13)/(Normalize!I13-Normalize!G13))*5))))/3 -> 5 | N37: 6 | O37: ירושלים | P37: 0
D38: 1.2.1 | E38: מספר מחירונים זמינים | H38: N | I38: 60 | K38: =D38 -> 1.2.1 | N38: 7 | O38: איו"ש | P38: 0
D39: 1.2.2 | E39: מחיר מזערי במחירונים | H39: NV | I39: 20 | K39: =D39 -> 1.2.2 | N39: 8 | O39: שפלה | P39: 0
D40: 1.2.3 | E40: מחיר מירבי במחירונים | H40: NV | I40: 30 | K40: =D40 -> 1.2.3 | N40: 9 | O40: דרום | P40: 0
C41: 1.3 | D41: משקפיים | H41: < | I41: =(IF(I42=Normalize!G15,5,IF(I42<Normalize!G15,5,IF(I42>Normalize!I15,0,((I42-Normalize!G15)/(Normalize!I15-Normalize!G15))*5)))+IF(I43=Normalize!G16,5,IF(I43<Normalize!G16,5,IF(I43>Normalize!I16,0,5-((I43-Normalize!G16)/(Normalize!I16-Normalize!G16))*5)))+IF(I44=Normalize!G17,5,IF(I44<Normalize!G17,5,IF(I44>Normalize!I17,0,5-((I44-Normalize!G17)/(Normalize!I17-Normalize!G17))*5))))/3 -> 5 | N41: 10 | O41: אילת | P41: 0
D42: 1.3.1 | E42: מספר מחירונים זמינים | H42: N | I42: 5 | K42: =D42 -> 1.3.1 | P42: =SUM(P32:P41)/5 -> 1
D43: 1.3.2 | E43: מחיר מזערי במחירונים | H43: NV | I43: 8 | K43: =D43 -> 1.3.2
D44: 1.3.3 | E44: מחיר מירבי במחירונים | H44: NV | I44: 22 | K44: =D44 -> 1.3.3
C45: 1.4 | D45: שרשראות | H45: < | I45: =(IF(I46=Normalize!G19,5,IF(I46<Normalize!G19,5,IF(I46>Normalize!I19,0,((I46-Normalize!G19)/(Normalize!I19-Normalize!G19))*5)))+IF(I47=Normalize!G20,5,IF(I47<Normalize!G20,5,IF(I47>Normalize!I20,0,5-((I47-Normalize!G20)/(Normalize!I20-Normalize!G20))*5)))+IF(I48=Normalize!G21,5,IF(I48<Normalize!G21,5,IF(I48>Normalize!I21,0,5-((I48-Normalize!G21)/(Normalize!I21-Normalize!G21))*5))))/3 -> 5
D46: 1.4.1 | E46: מספר מחירונים זמינים | H46: N | I46: 5 | K46: =D46 -> 1.4.1 | N46: 2
D47: 1.4.2 | E47: מחיר מזערי במחירונים | H47: NV | I47: 8 | K47: =D47 -> 1.4.2 | N47: ישובי סניף /ים /שליחויות /שירות | P47: כן=5 / לא=0 | Q47: איזור
D48: 1.4.3 | E48: מחיר מירבי במחירונים | H48: NV | I48: 22 | K48: =D48 -> 1.4.3 | N48: 1 | O48: בית שאן | P48: 0 | Q48: צפון
C49: 1.5 | D49: קונפטי | H49: < | I49: =(IF(I50=Normalize!G23,5,IF(I50<Normalize!G23,5,IF(I50>Normalize!I23,0,((I50-Normalize!G23)/(Normalize!I23-Normalize!G23))*5)))+IF(I51=Normalize!G24,5,IF(I51<Normalize!G24,5,IF(I51>Normalize!I24,0,5-((I51-Normalize!G24)/(Normalize!I24-Normalize!G24))*5)))+IF(I52=Normalize!G25,5,IF(I52<Normalize!G25,5,IF(I52>Normalize!I25,0,5-((I52-Normalize!G25)/(Normalize!I25-Normalize!G25))*5))))/3 -> 5 | N49: 2 | O49: טבריה | P49: 0 | Q49: צפון
D50: 1.5.1 | E50: מספר מחירונים זמינים | H50: N | I50: 5 | K50: =D50 -> 1.5.1 | N50: 3 | O50: טירת כרמל | P50: 0 | Q50: צפון
D51: 1.5.2 | E51: מחיר מזערי במחירונים | H51: NV | I51: 8 | K51: =D51 -> 1.5.2 | N51: 4 | O51: טמרה | P51: 0 | Q51: צפון
D52: 1.5.3 | E52: מחיר מירבי במחירונים | H52: NV | I52: 22 | K52: =D52 -> 1.5.3 | N52: 5 | O52: יקנעם עילית | P52: 0 | Q52: צפון
C53: 1.6 | D53: ספריי שלג | H53: < | I53: =(IF(I54=Normalize!G27,5,IF(I54<Normalize!G27,5,IF(I54>Normalize!I27,0,((I54-Normalize!G27)/(Normalize!I27-Normalize!G27))*5)))+IF(I55=Normalize!G28,5,IF(I55<Normalize!G28,5,IF(I55>Normalize!I28,0,5-((I55-Normalize!G28)/(Normalize!I28-Normalize!G28))*5)))+IF(I56=Normalize!G29,5,IF(I56<Normalize!G29,5,IF(I56>Normalize!I29,0,5-((I56-Normalize!G29)/(Normalize!I29-Normalize!G29))*5))))/3 -> 5 | N53: 6 | O53: כרמיאל | P53: 0 | Q53: צפון
D54: 1.6.1 | E54: מספר מחירונים זמינים | H54: N | I54: 5 | K54: =D54 -> 1.6.1 | N54: 7 | O54: מגדל העמק | P54: 0 | Q54: צפון
D55: 1.6.2 | E55: מחיר מזערי במחירונים | H55: NV | I55: 8 | K55: =D55 -> 1.6.2 | N55: 8 | O55: מעלות- תרשיחא | P55: 5 | Q55: צפון
D56: 1.6.3 | E56: מחיר מירבי במחירונים | H56: NV | I56: 22 | K56: =D56 -> 1.6.3 | N56: 9 | O56: נהריה | P56: 0 | Q56: צפון
C57: 1.7 | D57: מתנפחים | H57: < | I57: =(IF(I58=Normalize!G31,5,IF(I58<Normalize!G31,5,IF(I58>Normalize!I31,0,((I58-Normalize!G31)/(Normalize!I31-Normalize!G31))*5)))+IF(I59=Normalize!G32,5,IF(I59<Normalize!G32,5,IF(I59>Normalize!I32,0,5-((I59-Normalize!G32)/(Normalize!I32-Normalize!G32))*5)))+IF(I60=Normalize!G33,5,IF(I60<Normalize!G33,5,IF(I60>Normalize!I33,0,5-((I60-Normalize!G33)/(Normalize!I33-Normalize!G33))*5))))/3 -> 5 | N57: 10 | O57: נוף הגליל | P57: 0 | Q57: צפון | R57: 1
D58: 1.7.1 | E58: מספר מחירונים זמינים | H58: N | I58: 5 | K58: =D58 -> 1.7.1 | N58: 11 | O58: נצרת | P58: 5 | Q58: צפון
...

Sheet Normalize
B2: פרמטרים לנירמול
B4: 1 | C4: מדדים תעריפיים (כולל מע"מ) | G4: MIN | H4: AVR | I4: MAX
B5: 1 | C5: מדגם מחירים (פריט שאינו נמכר, המחיר=999)
C6: 1.1 | D6: בלונים
D7: 1.1.1 | E7: מספר מחירונים זמינים | G7: 130 | H7: =(G7+I7)/2 -> 130 | I7: 130
D8: 1.1.2 | E8: מחיר מזערי במחירונים | G8: 60 | H8: =(G8+I8)/2 -> 60 | I8: 60
D9: 1.1.3 | E9: מחיר מירבי במחירונים | G9: 90 | H9: =(G9+I9)/2 -> 90 | I9: 90
C10: 1.2 | D10: כובעים
D11: 1.2.1 | E11: מספר מחירונים זמינים | G11: 60 | H11: =(G11+I11)/2 -> 60 | I11: 60
D12: 1.2.2 | E12: מחיר מזערי במחירונים | G12: 20 | H12: =(G12+I12)/2 -> 20 | I12: 20
D13: 1.2.3 | E13: מחיר מירבי במחירונים | G13: 30 | H13: =(G13+I13)/2 -> 30 | I13: 30
C14: 1.3 | D14: משקפיים
D15: 1.3.1 | E15: מספר מחירונים זמינים | G15: 5 | H15: =(G15+I15)/2 -> 5 | I15: 5
D16: 1.3.2 | E16: מחיר מזערי במחירונים | G16: 8 | H16: =(G16+I16)/2 -> 8 | I16: 8
D17: 1.3.3 | E17: מחיר מירבי במחירונים | G17: 22 | H17: =(G17+I17)/2 -> 22 | I17: 22
C18: 1.4 | D18: שרשראות
D19: 1.4.1 | E19: מספר מחירונים זמינים | G19: 5 | H19: =(G19+I19)/2 -> 5 | I19: 5
D20: 1.4.2 | E20: מחיר מזערי במחירונים | G20: 8 | H20: =(G20+I20)/2 -> 8 | I20: 8
D21: 1.4.3 | E21: מחיר מירבי במחירונים | G21: 22 | H21: =(G21+I21)/2 -> 22 | I21: 22
C22: 1.5 | D22: קונפטי
D23: 1.5.1 | E23: מספר מחירונים זמינים | G23: 5 | H23: =(G23+I23)/2 -> 5 | I23: 5
D24: 1.5.2 | E24: מחיר מזערי במחירונים | G24: 8 | H24: =(G24+I24)/2 -> 8 | I24: 8
D25: 1.5.3 | E25: מחיר מירבי במחירונים | G25: 22 | H25: =(G25+I25)/2 -> 22 | I25: 22
C26: 1.6 | D26: ספריי שלג
D27: 1.6.1 | E27: מספר מחירונים זמינים | G27: 5 | H27: =(G27+I27)/2 -> 5 | I27: 5
D28: 1.6.2 | E28: מחיר מזערי במחירונים | G28: 8 | H28: =(G28+I28)/2 -> 8 | I28: 8
D29: 1.6.3 | E29: מחיר מירבי במחירונים | G29: 22 | H29: =(G29+I29)/2 -> 22 | I29: 22
C30: 1.7 | D30: מתנפחים
D31: 1.7.1 | E31: מספר מחירונים זמינים | G31: 5 | H31: =(G31+I31)/2 -> 5 | I31: 5
D32: 1.7.2 | E32: מחיר מזערי במחירונים | G32: 8 | H32: =(G32+I32)/2 -> 8 | I32: 8
D33: 1.7.3 | E33: מחיר מירבי במחירונים | G33: 22 | H33: =(G33+I33)/2 -> 22 | I33: 22
C34: 1.8 | D34: דגלים
D35: 1.8.1 | E35: מספר מחירונים זמינים | G35: 5 | H35: =(G35+I35)/2 -> 5 | I35: 5
D36: 1.8.2 | E36: מחיר מזערי במחירונים | G36: 8 | H36: =(G36+I36)/2 -> 8 | I36: 8
D37: 1.8.3 | E37: מחיר מירבי במחירונים | G37: 22 | H37: =(G37+I37)/2 -> 22 | I37: 22
C38: 1.9 | D38: צמידים
D39: 1.9.1 | E39: מספר מחירונים זמינים | G39: 5 | H39: =(G39+I39)/2 -> 5 | I39: 5
D40: 1.9.2 | E40: מחיר מזערי במחירונים | G40: 8 | H40: =(G40+I40)/2 -> 8 | I40: 8
D41: 1.9.3 | E41: מחיר מירבי במחירונים | G41: 22 | H41: =(G41+I41)/2 -> 22 | I41: 22
C42: 1.1 | D42: מסכות
...
