Workbook

Sheet Main
B2: Ver.#1 | H2: קופות גמל לניהול כספי תגמולים לעצמאיים | I2: 30 | J2: חברות פעילות בתחום
B4: השקעות | F4: החברה | G4: ________ | H4: מתוך | J4: חברות במערכת | N4: Website & Service improvement Guide
H5: ככל ששטח המצולע גדול יותר - החברה איכותית יותר. להגדלת התרשים - עמדו עליו: | N5: המלצות לשיפור האתר, השירות והמותג מהות ההמלצות לעדכון הפרמטרים הינה מקסימיזציה יחסית בהשוואה למיטבי מבין כלל אתרי תחום הפעילות ובכך לשדרג את מיקום האתר בדירוג הרייטינג הכולל והיחסי שלו
B6: דירוג הרייטינג היחסי הכולל | G6: > | H6: ככל שהדירוגים בעמודה גבוהים יותר - החברה איכותית יותר | I6: =(I8*H8 + I10*H10 + I12*H12 + I14*H14 + I16*H16 + I18*H18 + I20*H20 + I28*H28 + I30*H30)/SUM(H8,H10,H12,H14,H16,H18,H20,H22,H28,H30) -> 3.2201063
B8: 1 | C8: מדגם תעריפים | H8: 2 | I8: =I32 -> 5
B10: 2 | C10: ביצועים ממוצעים | H10: 1.8 | I10: =I71 -> 1.9092938
B14: 3 | C14: =C90 -> ערכיות רב-שכבתית | H14: 1.6 | I14: =I90 -> 3.0769231
B16: 4 | C16: =C169 -> גודל ופריסה | H16: 1.4 | I16: =I169 -> 2.4145299
B18: 5 | C18: =C174 -> רמת שירות וממשקים | H18: 1.5 | I18: =I174 -> 2.1875
B20: 6 | C20: =C181 -> אמינות ושקיפות | H20: 1.4 | I20: =I188 -> 3.75
B28: 7 | C28: =C188 -> סייבר ושמירת פרטיות | H28: 1 | I28: =I188 -> 3.75
B30: 8 | C30: =C206 -> נוכחות דיגיטלית | H30: 1 | I30: =I206 -> 3.6538462
B32: 1 | C32: מדגם תעריפים מירביים (כולל מע"מ) | H32: דירוג משוקלל מנורמל > | I32: =I33 -> 5
B33: 1 | C33: מדגם תעריפים - תעריף שאינו זמין, המחיר=999) | H33: << | I33: =(I34*3+I38*3+I42*3+I46*3+I50*3+I54*3+I58*3+I62*3+I66*3)/27 -> 5
C34: 1.1 | D34: תשלום דמי ניהול – % לשנה | H34: < | I34: =(IF(I35=Normalize!G5,5,IF(I35<Normalize!G5,5,IF(I35>Normalize!I5,0,((I35-Normalize!G5)/(Normalize!I5-Normalize!G5))*5)))+IF(I36=Normalize!G6,5,IF(I36<Normalize!G6,5,IF(I36>Normalize!I6,0,5-((I36-Normalize!G6)/(Normalize!I6-Normalize!G6))*5)))+IF(I37=Normalize!G7,5,IF(I37<Normalize!G7,5,IF(I37>Normalize!I7,0,5-((I37-Normalize!G7)/(Normalize!I7-Normalize!G7))*5))))/3 -> 5 | L34: הערות /הבהרות למשתנים
D35: 1.1.1 | E35: מספר מחירונים זמינים | H35: N | I35: 5 | K35: =D35 -> 1.1.1
D36: 1.1.2 | E36: מחיר מזערי במחירונים | H36: NV | I36: 0.006 | K36: =D36 -> 1.1.2
D37: 1.1.3 | E37: מחיר מירבי במחירונים | H37: NV | I37: 0.008 | K37: =D37 -> 1.1.3
C38: 1.2 | D38: ייעוץ בתחום הפנסיוני –מחיר שעה | H38: < | I38: =(IF(I39=Normalize!G9,5,IF(I39<Normalize!G9,5,IF(I39>Normalize!I9,0,((I39-Normalize!G9)/(Normalize!I9-Normalize!G9))*5)))+IF(I40=Normalize!G10,5,IF(I40<Normalize!G10,5,IF(I40>Normalize!I10,0,5-((I40-Normalize!G10)/(Normalize!I10-Normalize!G10))*5)))+IF(I41=Normalize!G11,5,IF(I41<Normalize!G11,5,IF(I41>Normalize!I11,0,5-((I41-Normalize!G11)/(Normalize!I11-Normalize!G11))*5))))/3 -> 5
D39: 1.2.1 | E39: מספר מחירונים זמינים | H39: N | I39: 5 | K39: =D39 -> 1.2.1
D40: 1.2.2 | E40: מחיר מזערי במחירונים | H40: NV | I40: 80 | K40: =D40 -> 1.2.2
D41: 1.2.3 | E41: מחיר מירבי במחירונים | H41: NV | I41: 90 | K41: =D41 -> 1.2.3
C42: 1.3 | D42: ניהול תיק השקעות אישי – % מהסכום המנוהל | H42: < | I42: =(IF(I43=Normalize!G13,5,IF(I43<Normalize!G13,5,IF(I43>Normalize!I13,0,((I43-Normalize!G13)/(Normalize!I13-Normalize!G13))*5)))+IF(I44=Normalize!G14,5,IF(I44<Normalize!G14,5,IF(I44>Normalize!I14,0,5-((I44-Normalize!G14)/(Normalize!I14-Normalize!G14))*5)))+IF(I45=Normalize!G15,5,IF(I45<Normalize!G15,5,IF(I45>Normalize!I15,0,5-((I45-Normalize!G15)/(Normalize!I15-Normalize!G15))*5))))/3 -> 5
D43: 1.3.1 | E43: מספר מחירונים זמינים | H43: N | I43: 5 | K43: =D43 -> 1.3.1
D44: 1.3.2 | E44: מחיר מזערי במחירונים | H44: NV | I44: 0.006 | K44: =D44 -> 1.3.2
D45: 1.3.3 | E45: מחיר מירבי במחירונים | H45: NV | I45: 0.008 | K45: =D45 -> 1.3.3
C46: 1.4 | D46: עמלות הפקדה /משיכה – % | H46: < | I46: =(IF(I47=Normalize!G17,5,IF(I47<Normalize!G17,5,IF(I47>Normalize!I17,0,((I47-Normalize!G17)/(Normalize!I17-Normalize!G17))*5)))+IF(I48=Normalize!G18,5,IF(I48<Normalize!G18,5,IF(I48>Normalize!I18,0,5-((I48-Normalize!G18)/(Normalize!I18-Normalize!G18))*5)))+IF(I49=Normalize!G19,5,IF(I49<Normalize!G19,5,IF(I49>Normalize!I19,0,5-((I49-Normalize!G19)/(Normalize!I19-Normalize!G19))*5))))/3 -> 5
D47: 1.4.1 | E47: מספר מחירונים זמינים | H47: N | I47: 5 | K47: =D47 -> 1.4.1
D48: 1.4.2 | E48: מחיר מזערי במחירונים | H48: NV | I48: 0.006 | K48: =D48 -> 1.4.2
D49: 1.4.3 | E49: מחיר מירבי במחירונים | H49: NV | I49: 0.008 | K49: =D49 -> 1.4.3
C50: 1.5 | D50: עמלות השקעות במניות ואגרות חוב – % | H50: < | I50: =(IF(I51=Normalize!G21,5,IF(I51<Normalize!G21,5,IF(I51>Normalize!I21,0,((I51-Normalize!G21)/(Normalize!I21-Normalize!G21))*5)))+IF(I52=Normalize!G22,5,IF(I52<Normalize!G22,5,IF(I52>Normalize!I22,0,5-((I52-Normalize!G22)/(Normalize!I22-Normalize!G22))*5)))+IF(I53=Normalize!G23,5,IF(I53<Normalize!G23,5,IF(I53>Normalize!I23,0,5-((I53-Normalize!G23)/(Normalize!I23-Normalize!G23))*5))))/3 -> 5
D51: 1.5.1 | E51: מספר מחירונים זמינים | H51: N | I51: 5 | K51: =D51 -> 1.5.1
D52: 1.5.2 | E52: מחיר מזערי במחירונים | H52: NV | I52: 0.006 | K52: =D52 -> 1.5.2
D53: 1.5.3 | E53: מחיר מירבי במחירונים | H53: NV | I53: 0.008 | K53: =D53 -> 1.5.3
C54: 1.6 | D54: דמי ניהול משכנתא עצמאית – % | H54: < | I54: =(IF(I55=Normalize!G25,5,IF(I55<Normalize!G25,5,IF(I55>Normalize!I25,0,((I55-Normalize!G25)/(Normalize!I25-Normalize!G25))*5)))+IF(I56=Normalize!G26,5,IF(I56<Normalize!G26,5,IF(I56>Normalize!I26,0,5-((I56-Normalize!G26)/(Normalize!I26-Normalize!G26))*5)))+IF(I57=Normalize!G27,5,IF(I57<Normalize!G27,5,IF(I57>Normalize!I27,0,5-((I57-Normalize!G27)/(Normalize!I27-Normalize!G27))*5))))/3 -> 5
D55: 1.6.1 | E55: מספר מחירונים זמינים | H55: N | I55: 5 | K55: =D55 -> 1.6.1
D56: 1.6.2 | E56: מחיר מזערי במחירונים | H56: NV | I56: 0.006 | K56: =D56 -> 1.6.2
D57: 1.6.3 | E57: מחיר מירבי במחירונים | H57: NV | I57: 0.008 | K57: =D57 -> 1.6.3
C58: 1.7 | D58: ייעוץ על פנסיה בשירותים בלעדיים - מחיר פגישה | H58: < | I58: =(IF(I59=Normalize!G29,5,IF(I59<Normalize!G29,5,IF(I59>Normalize!I29,0,((I59-Normalize!G29)/(Normalize!I29-Normalize!G29))*5)))+IF(I60=Normalize!G30,5,IF(I60<Normalize!G30,5,IF(I60>Normalize!I30,0,5-((I60-Normalize!G30)/(Normalize!I30-Normalize!G30))*5)))+IF(I61=Normalize!G31,5,IF(I61<Normalize!G31,5,IF(I61>Normalize!I31,0,5-((I61-Normalize!G31)/(Normalize!I31-Normalize!G31))*5))))/3 -> 5
D59: 1.7.1 | E59: מספר מחירונים זמינים | H59: N | I59: 5 | K59: =D59 -> 1.7.1
...

Sheet Normalize
B1: פרמטרים לנירמול | G1: MIN | H1: AVR | I1: MAX
B2: 1 | C2: מדדים תעריפיים (כולל מע"מ)
B3: 1 | C3: מדדים תעריפיים (כולל מע"מ)
C4: 1.1 | D4: תשלום דמי ניהול – % לשנה
D5: 1.1.1 | E5: מספר מחירונים זמינים | G5: 5 | H5: =(G5+I5)/2 -> 5 | I5: 5
D6: 1.1.2 | E6: מחיר מזערי במחירונים | G6: 0.006 | H6: =(G6+I6)/2 -> 0.006 | I6: 0.006
D7: 1.1.3 | E7: מחיר מירבי במחירונים | G7: 0.008 | H7: =(G7+I7)/2 -> 0.008 | I7: 0.008
C8: 1.2 | D8: ייעוץ בתחום הפנסיוני –מחיר שעה
D9: 1.2.1 | E9: מספר מחירונים זמינים | G9: 5 | H9: =(G9+I9)/2 -> 5 | I9: 5
D10: 1.2.2 | E10: מחיר מזערי במחירונים | G10: 80 | H10: =(G10+I10)/2 -> 80 | I10: 80
D11: 1.2.3 | E11: מחיר מירבי במחירונים | G11: 90 | H11: =(G11+I11)/2 -> 90 | I11: 90
C12: 1.3 | D12: ניהול תיק השקעות אישי – % מהסכום המנוהל
D13: 1.3.1 | E13: מספר מחירונים זמינים | G13: 5 | H13: =(G13+I13)/2 -> 5 | I13: 5
D14: 1.3.2 | E14: מחיר מזערי במחירונים | G14: 0.006 | H14: =(G14+I14)/2 -> 0.006 | I14: 0.006
D15: 1.3.3 | E15: מחיר מירבי במחירונים | G15: 0.008 | H15: =(G15+I15)/2 -> 0.008 | I15: 0.008
C16: 1.4 | D16: עמלות הפקדה /משיכה – %
D17: 1.4.1 | E17: מספר מחירונים זמינים | G17: 5 | H17: =(G17+I17)/2 -> 5 | I17: 5
D18: 1.4.2 | E18: מחיר מזערי במחירונים | G18: 0.006 | H18: =(G18+I18)/2 -> 0.006 | I18: 0.006
D19: 1.4.3 | E19: מחיר מירבי במחירונים | G19: 0.008 | H19: =(G19+I19)/2 -> 0.008 | I19: 0.008
C20: 1.5 | D20: עמלות השקעות במניות ואגרות חוב – %
D21: 1.5.1 | E21: מספר מחירונים זמינים | G21: 5 | H21: =(G21+I21)/2 -> 5 | I21: 5
D22: 1.5.2 | E22: מחיר מזערי במחירונים | G22: 0.006 | H22: =(G22+I22)/2 -> 0.006 | I22: 0.006
D23: 1.5.3 | E23: מחיר מירבי במחירונים | G23: 0.008 | H23: =(G23+I23)/2 -> 0.008 | I23: 0.008
C24: 1.6 | D24: דמי ניהול משכנתא עצמאית – %
D25: 1.6.1 | E25: מספר מחירונים זמינים | G25: 5 | H25: =(G25+I25)/2 -> 5 | I25: 5
D26: 1.6.2 | E26: מחיר מזערי במחירונים | G26: 0.006 | H26: =(G26+I26)/2 -> 0.006 | I26: 0.006
D27: 1.6.3 | E27: מחיר מירבי במחירונים | G27: 0.008 | H27: =(G27+I27)/2 -> 0.008 | I27: 0.008
C28: 1.7 | D28: ייעוץ על פנסיה בשירותים בלעדיים - מחיר פגישה
D29: 1.7.1 | E29: מספר מחירונים זמינים | G29: 5 | H29: =(G29+I29)/2 -> 5 | I29: 5
D30: 1.7.2 | E30: מחיר מזערי במחירונים | G30: 80 | H30: =(G30+I30)/2 -> 80 | I30: 80
D31: 1.7.3 | E31: מחיר מירבי במחירונים | G31: 90 | H31: =(G31+I31)/2 -> 90 | I31: 90
C32: 1.8 | D32: שירותי אכיפת רגולציה או ייעוץ רגולטורי – מחיר שעה
D33: 1.8.1 | E33: מספר מחירונים זמינים | G33: 5 | H33: =(G33+I33)/2 -> 5 | I33: 5
D34: 1.8.2 | E34: מחיר מזערי במחירונים | G34: 80 | H34: =(G34+I34)/2 -> 80 | I34: 80
D35: 1.8.3 | E35: מחיר מירבי במחירונים | G35: 90 | H35: =(G35+I35)/2 -> 90 | I35: 90
C36: 1.9 | D36: שכר טרחה לטיפול בפנסיה – לכל טיפול
D37: 1.9.1 | E37: מספר מחירונים זמינים | G37: 5 | H37: =(G37+I37)/2 -> 5 | I37: 5
D38: 1.9.2 | E38: מחיר מזערי במחירונים | G38: 80 | H38: =(G38+I38)/2 -> 80 | I38: 80
D39: 1.9.3 | E39: מחיר מירבי במחירונים | G39: 90 | H39: =(G39+I39)/2 -> 90 | I39: 90
B41: 2 | C41: ביצועים ממוצעים - לסוף שנת הלוח הקודמת
...
