Workbook

Sheet Main
B2: Ver.#1 | E2: רשתות כלים חד-פעמיים | H2: 12 | I2: חברות פעילות בתחום
B4: מוצרים | D4: החברה | E4: ________ | G4: מתוך | I4: חברות במערכת | T4: Website & Service improvement Guide
G5: ככל ששטח המצולע גדול יותר - החברה איכותית יותר. להגדלת התרשים - עמדו עליו: | T5: המלצות לשיפור האתר, השירות והמותג מהות ההמלצות לעדכון הפרמטרים הינה מקסימיזציה יחסית בהשוואה למיטבי מבין כלל אתרי תחום הפעילות ובכך לשדרג את מיקום האתר בדירוג הרייטינג הכולל והיחסי שלו
B6: דירוג הרייטינג היחסי הכולל | E6: > | G6: ככל שהדירוגים בעמודה גבוהים יותר - החברה איכותית יותר | H6: =(H8*G8 + H10*G10 + H14*G14 + H16*G16 + H18*G18 + H20*G20 + H24*G24)/SUM(G8,G10,G14,G16,G18,G20,G22,G24) -> 2.8571047
B8: 1 | C8: מדדים תעריפיים | G8: 2 | H8: =H32 -> 4.6938776
B10: 2 | C10: =C63 -> ערכיות רב-שכבתית | G10: 1.8 | H10: =H63 -> 1.2269345
B14: 3 | C14: =C114 -> גודל ופריסה | G14: 1.6 | H14: =H114 -> 2.0841598
B16: 4 | C16: =C120 -> רמת שירות וממשקים | G16: 1.4 | H16: =H120 -> 0
B18: 5 | C18: =C127 -> אמינות ושקיפות | G18: 1.5 | H18: =H127 -> 4.6
B20: 6 | C20: =C134 -> סייבר ושמירת פרטיות | G20: 1.4 | H20: =H134 -> 3.75
B24: 7 | C24: =C152 -> נוכחות דיגיטלית | G24: 0.6 | H24: =H152 -> 3.9121419
B32: 1 | C32: מדדים תעריפיים (כולל מע"מ) | G32: דירוג משוקלל מנורמל > | H32: =(H34*5+H41+H54)/7 -> 4.6938776 | M32: 1
M33: איזור סניף /ים | O33: כן=5 / לא=0
B34: 1 | C34: מדגם מחירים (פריט שאינו נמכר, המחיר=999) | G34: < | H34: =(IF(H35=Normalize!E6,5,IF(H35<Normalize!E6,5,IF(H35>Normalize!G6,0,5-((H35-Normalize!E6)/(Normalize!G6-Normalize!E6))*5)))+IF(H36=Normalize!E7,5,IF(H36<Normalize!E7,5,IF(H36>Normalize!G7,0,5-((H36-Normalize!E7)/(Normalize!G7-Normalize!E7))*5)))+IF(H37=Normalize!E8,5,IF(H37<Normalize!E8,5,IF(H37>Normalize!G8,0,5-((H37-Normalize!E8)/(Normalize!G8-Normalize!E8))*5)))+IF(H38=Normalize!E9,5,IF(H38<Normalize!E9,5,IF(H38>Normalize!G9,0,5-((H38-Normalize!E9)/(Normalize!G9-Normalize!E9))*5)))+IF(H39=Normalize!E10,5,IF(H39<Normalize!E10,5,IF(H39>Normalize!G10,0,5-((H39-Normalize!E10)/(Normalize!G10-Normalize!E10))*5))))/5 -> 5 | K34: הערות /הבהרות למשתנים | M34: 1 | N34: צפון | O34: 0
C35: 1.1 | D35: מחיר כוסות אספרסו | G35: NV | H35: 0.6 | J35: =C35 -> 1.1 | M35: 2 | N35: חיפה והקריות | O35: 0
C36: 1.2 | D36: מחיר כוסות שתיה קרה | G36: NV | H36: 0.5 | J36: =C36 -> 1.2 | M36: 3 | N36: שרון | O36: 0
C37: 1.3 | D37: מחיר כפות | G37: NV | H37: 0.5 | J37: =C37 -> 1.3 | M37: 4 | N37: מרכז | O37: 0
C38: 1.4 | D38: מחיר צלחות מרק | G38: NV | H38: 0.4 | J38: =C38 -> 1.4 | M38: 5 | N38: גוש דן | O38: 5
C39: 1.5 | D39: מחיר קשיות | G39: NV | H39: 0.1 | J39: =C39 -> 1.5 | M39: 6 | N39: ירושלים | O39: 0
M40: 7 | N40: איו"ש | O40: 0
B41: 2 | C41: מחירי שירות /משלוח (באיזור העדר שליחות, המחיר=999) | G41: < | H41: =(IF(H42=Normalize!E13,5,IF(H42<Normalize!E13,5,IF(H42>Normalize!G13,0,5-((H42-Normalize!E13)/(Normalize!G13-Normalize!E13))*5)))+ IF(H43=Normalize!E14,5,IF(H43<Normalize!E14,5,IF(H43>Normalize!G14,0,5-((H43-Normalize!E14)/(Normalize!G14-Normalize!E14))*5)))+ IF(H44=Normalize!E15,5,IF(H44<Normalize!E15,5,IF(H44>Normalize!G15,0,5-((H44-Normalize!E15)/(Normalize!G15-Normalize!E15))*5)))+ IF(H45=Normalize!E16,5,IF(H45<Normalize!E16,5,IF(H45>Normalize!G16,0,5-((H45-Normalize!E16)/(Normalize!G16-Normalize!E16))*5)))+ IF(H46=Normalize!E17,5,IF(H46<Normalize!E17,5,IF(H46>Normalize!G17,0,5-((H46-Normalize!E17)/(Normalize!G17-Normalize!E17))*5)))+ IF(H47=Normalize!E18,5,IF(H47<Normalize!E18,5,IF(H47>Normalize!G18,0,5-((H47-Normalize!E18)/(Normalize!G18-Normalize!E18))*5)))+ IF(H48=Normalize!E19,5,IF(H48<Normalize!E19,5,IF(H48>Normalize!G19,0,5-((H48-Normalize!E19)/(Normalize!G19-Normalize!E19))*5)))+ IF(H49=Normalize!E20,5,IF(H49<Normalize!E20,5,IF(H49>Normalize!G20,0,5-((H49-Normalize!E20)/(Normalize!G20-Normalize!E20))*5)))+ IF(H50=Normalize!E21,5,IF(H50<Normalize!E21,5,IF(H50>Normalize!G21,0,5-((H50-Normalize!E21)/(Normalize!G21-Normalize!E21))*5)))+ IF(H51=Normalize!E22,5,IF(H51<Normalize!E22,5,IF(H51>Normalize!G22,0,5-((H51-Normalize!E22)/(Normalize!G22-Normalize!E22))*5)))+ IF(H52=Normalize!E23,5,IF(H52<Normalize!E23,5,IF(H52>Normalize!G23,0,5-((H52-Normalize!E23)/(Normalize!G23-Normalize!E23))*5))))/11 -> 5 | M41: 8 | N41: שפלה | O41: 0
C42: 1.1 | D42: דואר רשום | G42: NV | H42: 45 | J42: =C42 -> 1.1 | M42: 9 | N42: דרום | O42: 0
C43: 1.2 | D43: צפון | G43: NV | H43: 125 | J43: =C43 -> 1.2 | M43: 10 | N43: אילת | O43: 0
C44: 1.3 | D44: חיפה והקריות | G44: NV | H44: 66 | J44: =C44 -> 1.3 | O44: =SUM(O34:O43)/5 -> 1
C45: 1.4 | D45: שרון | G45: NV | H45: 275 | J45: =C45 -> 1.4
C46: 1.5 | D46: מרכז | G46: NV | H46: 90 | J46: =C46 -> 1.5
C47: 1.6 | D47: גוש-דן | G47: NV | H47: 75 | J47: =C47 -> 1.6
C48: 1.7 | D48: ירושלים | G48: NV | H48: 75 | J48: =C48 -> 1.7
C49: 1.8 | D49: איו"ש | G49: NV | H49: 60 | J49: =C49 -> 1.8
C50: 1.9 | D50: שפלה | G50: NV | H50: 100 | J50: =C50 -> 1.9
C51: 1.10 | D51: דרום | G51: NV | H51: 55 | J51: =C51 -> 1.10
C52: 1.11 | D52: אילת | G52: NV | H52: 275 | J52: =C52 -> 1.11
M53: 2
B54: 3 | C54: אמצעי תשלום ואשראי זמינים | G54: < | H54: =SUM(H55:H61)/7 -> 2.8571429 | M54: ישובי סניף /ים /שליחויות /שירות | O54: כן=5 / לא=0 | P54: איזור
C55: 3.1 | D55: העברות | G55: כן=5 / לא=0 | H55: 5 | J55: =C55 -> 3.1 | M55: 1 | N55: בית שאן | O55: 0 | P55: צפון
C56: 3.2 | D56: פייפאל | G56: כן=5 / לא=0 | H56: 5 | J56: =C56 -> 3.2 | M56: 2 | N56: טבריה | O56: 0 | P56: צפון
C57: 3.3 | D57: אפליקציות תשלומים | G57: כן=5 / לא=0 | H57: 0 | J57: =C57 -> 3.3 | M57: 3 | N57: טירת כרמל | O57: 0 | P57: צפון
C58: 3.4 | D58: ביטקוין | G58: כן=5 / לא=0 | H58: 0 | J58: =C58 -> 3.4 | M58: 4 | N58: טמרה | O58: 0 | P58: צפון
C59: 3.5 | D59: כרטיסי אשראי | G59: כן=5 / לא=0 | H59: 5 | J59: =C59 -> 3.5 | M59: 5 | N59: יקנעם עילית | O59: 0 | P59: צפון
C60: 3.6 | D60: כרטיסי חיוב ישיר | G60: כן=5 / לא=0 | H60: 0 | J60: =C60 -> 3.6 | M60: 6 | N60: כרמיאל | O60: 0 | P60: צפון
...

Sheet Normalize
B2: פרמטרים לנירמול
B4: 1 | C4: מדדים תעריפיים מירביים - לא במבצע (כולל מע"מ)
B5: 1 | C5: מדגם מחירים (פריט שאינו נמכר, המחיר=999) | E5: MIN | F5: AVR | G5: MAX
C6: 1.1 | D6: מחיר כוסות אספרסו | E6: 0.6 | F6: =(E6+G6)/2 -> 0.6 | G6: 0.6
C7: 1.2 | D7: מחיר כוסות שתיה קרה | E7: 0.5 | F7: =(E7+G7)/2 -> 0.5 | G7: 0.5
C8: 1.3 | D8: מחיר כפות | E8: 0.5 | F8: =(E8+G8)/2 -> 0.5 | G8: 0.5
C9: 1.4 | D9: מחיר צלחות מרק | E9: 0.4 | F9: =(E9+G9)/2 -> 0.4 | G9: 0.4
C10: 1.5 | D10: מחיר קשיות | E10: 0.1 | F10: =(E10+G10)/2 -> 0.1 | G10: 0.1
B12: 2 | C12: מחירי שירות /משלוח (באיזור העדר שליחות, המחיר=999)
C13: 1.1 | D13: דואר רשום | E13: 45 | F13: =(E13+G13)/2 -> 45 | G13: 45
C14: 1.3 | D14: חיפה והקריות | E14: 125 | F14: =(E14+G14)/2 -> 125 | G14: 125
C15: 1.2 | D15: צפון | E15: 66 | F15: =(E15+G15)/2 -> 66 | G15: 66
C16: 1.4 | D16: שרון | E16: 275 | F16: =(E16+G16)/2 -> 275 | G16: 275
C17: 1.5 | D17: מרכז | E17: 90 | F17: =(E17+G17)/2 -> 90 | G17: 90
C18: 1.6 | D18: גוש-דן | E18: 75 | F18: =(E18+G18)/2 -> 75 | G18: 75
C19: 1.7 | D19: ירושלים | E19: 75 | F19: =(E19+G19)/2 -> 75 | G19: 75
C20: 1.8 | D20: איו"ש | E20: 60 | F20: =(E20+G20)/2 -> 60 | G20: 60
C21: 1.9 | D21: שפלה | E21: 100 | F21: =(E21+G21)/2 -> 100 | G21: 100
C22: 1.10 | D22: דרום | E22: 55 | F22: =(E22+G22)/2 -> 55 | G22: 55
C23: 1.11 | D23: אילת | E23: 275 | F23: =(E23+G23)/2 -> 275 | G23: 275
B25: 2 | C25: ערכיות רב-שכבתית
C26: 2.3 | D26: זמן אספקה מירבי מובטח של הזמנת שליחות (ימי עסקים) | E26: 5 | F26: =(E26+G26)/2 -> 5 | G26: 5
B28: 4 | C28: רמת שירות וממשקים
B29: 1 | C29: זמן תגובה לפניות בצור קשר /תמיכה של האתר (שעות) | E29: 3 | F29: =(E29+G29)/2 -> 3 | G29: 3
B30: 2 | C30: זמן המתנה ממוצע למענה טלפוני של המוקד
C31: 2.1 | D31: בשעות הפעילות (דקות) | E31: 3 | F31: =(E31+G31)/2 -> 3 | G31: 3
C32: 2.2 | D32: מעבר לשעות הפעילות (דקות) | E32: 6 | F32: =(E32+G32)/2 -> 6 | G32: 6
B34: 5 | C34: אמינות ושקיפות
B35: 4 | C35: מספר המדדים הנשאבים אוטומטית מהאתר | E35: 30 | F35: =(E35+G35)/2 -> 30 | G35: 30
B36: 7 | C36: נוכחות דיגיטלית
B37: 1 | C37: ביצועי האתר - מהירות גלישה (ישראל)
C38: 1.1 | D38: צבע תוכן ראשון (FCP) - שניות | E38: 3 | F38: =(E38+G38)/2 -> 5 | G38: 7
C39: 1.2 | D39: שינוי פריסה מצטבר (CLS) | E39: 2 | F39: =(E39+G39)/2 -> 5 | G39: 8
C40: 1.3 | D40: אינטראקציה לצביעה הבאה (INP) - מילישניות | E40: 1 | F40: =(E40+G40)/2 -> 3 | G40: 5
B42: 2 | C42: דירוג המקובלות ברשת
C43: 2.1 | D43: פופולריות יחסית לתחום הפעילות (ישראל) | E43: 1000 | F43: =(E43+G43)/2 -> 1945 | G43: 2890
C44: 2.2 | D44: מספר ביקורים חודשי - אלפים | E44: 100 | F44: =(E44+G44)/2 -> 438.5 | G44: 777
C45: 2.3 | D45: משך שהיה ממוצע באתר - דקות | E45: 1 | F45: =(E45+G45)/2 -> 5 | G45: 9
C46: 2.4 | D46: קישורים נכנסים לאתר - Backlinks - אלפים | E46: 1 | F46: =(E46+G46)/2 -> 5 | G46: 9
C47: 2.5 | D47: הפניות לאתר - Refferings - אלפים | E47: 1 | F47: =(E47+G47)/2 -> 5 | G47: 9
...
