Workbook

Sheet README
A1: Merchant statement parse: sample Fiserv / CardPointe statement
A3: Source | B3: Sample Fiserv Statement.pdf (16 pages), card processing statement, period 07/01/2026 to 07/31/2026, corporate number 496115385882.
A4: Method | B4: Text was extracted from the PDF text layer and parsed with Python (regular expressions, decimal arithmetic). The parsed data was compared with the PDF text (every dollar amount on pages 2-16 matches in order, plus the page 1 values), then every table was validated in this workbook with live Excel formulas (see Checks).
A5: Result | B5: 77 of 78 checks pass: every parsed control total ties to the statement to the cent. The one REVIEW is a variance inside the source statement (3 interchange lines whose printed charge differs from rate x sales + transactions x fee). See Checks and Findings.
A6: Sign convention | B6: As printed on the statement: submitted sales and positive adjustments are positive; refunds, Paid by Others, disputes and fees are negative.
A7: Not parsed | B7: The compliance notice after page 16 (boilerplate, no data).
A8: Header | B8: Company and address on the Summary sheet are what page 1 visibly shows (ABC Company, DOWNINGTOWN PA 19335). The text layer holds different, more detailed text behind the overlay; it is not copied here (see Findings).
A10: Sheet | B10: Content
A11: Summary | B11: Statement header and account summary, with the summary equation recomputed.
A12: Cost Summary | B12: Effective rate (total and excluding AMEX), pass-through vs processor fees, effective rate by card brand and the 10 largest fee lines, all as live formulas.
A13: Trend | B13: 13-month sales trend from the page 1 chart, with YoY and MoM recomputed.
A14: Daily | B14: Summary By Day (31 dated rows incl. 06/30, the month-end charge and the total), row checks and tie-out to Funded.
A15: CardType | B15: Summary by Card Type with gross, refunds, net and average ticket recomputed.
... A24: Findings | B24: Parsing hazards found in this statement layout and source-statement variances to review.

Sheet Summary
A1: Statement header and account summary
A3: Statement
A4: Statement type | B4: CardConnect (Fiserv) card processing statement | C4: Logo reads cardconnect; contact site cardpointe.com
A5: Source file | B5: Sample Fiserv Statement.pdf | C5: 16 pages
A6: Corporate number | B6: 496115385882 | C6: Page 1 and the page headers show it truncated (4961); the full number is visible as the first Location ID in Summary By Location (page 3)
A7: Period start | B7: 46204
A8: Period end | B8: 46234
A9: Locations included | B9: 23 | C9: Printed on page 1; recounted in Checks
A10: Company (as displayed) | B10: ABC Company | C10: Exactly as printed on page 1
A11: City / state / ZIP (as displayed) | B11: DOWNINGTOWN PA 19335 | C11: No street address or contact name is visible on page 1
A12: Hidden text behind the header | B12: Yes | C12: The page 1 text layer holds a different company name, a contact name and a street address behind the overlay. Deliberately not copied here.
A13: Processor customer service | B13: 1-877-828-0720 / cardpointe.com
A15: Account Summary (page 1)
A16: Amount Submitted | B16: 8980209.2
A17: Paid by Others | B17: -1678631.3
A18: Disputes | B18: -1213.82
A19: Adjustments | B19: 0
A20: Fees | B20: -170258.04
A21: Amount Processed (statement) | B21: 7130106 | C21: Page 1 boxes are positioned out of label order in the text layer; mapped by equation and by the Total rows
A22: Amount Processed (computed) | B22: =SUM(B16:B20) -> 7130106
A23: Difference | B23: =B22-B21 -> 0
A25: New Customers | B25: 3481
A26: Repeat Customers | B26: 1548
A27: Avg. Ticket Size (statement) | B27: 808.08
A28: Avg. Ticket Size (computed) | B28: =ROUND(B16/CardType!G10,2) -> 808.08 | C28: Net submitted / net items (CardType total)
A29: Sales change Jul 25 vs Jul 26 | B29: 1.7827 | C29: Printed as "178.27% year over year"
A30: Sales change Jun 26 vs Jul 26 | B30: 0.0182 | C30: Printed as "1.82% month over month"

Sheet Cost Summary
A1: Cost summary: effective rate, pass-through and processor fees
A2: Fees are shown here as positive costs. Every value is a live formula on the Summary, CardType, FeeSummary and FeeDetail sheets.
A4: Volume
A5: Gross sales | B5: =CardType!D9 -> 9228078.2
A6: Refunds | B6: =CardType!F9 -> -247869
A7: Amount submitted (net) | B7: =Summary!B16 -> 8980209.2
A8: Transactions (sales + refunds) | B8: =CardType!G9 -> 11113
A9: Average ticket | B9: =Summary!B27 -> 808.08
A10: Refund rate (refunds / gross sales) | B10: =-CardType!F9/CardType!D9 -> 0.026860306
A12: Cost
A13: Total fees | B13: =-Summary!B20 -> 170258.04
A14: Effective rate (total fees / amount submitted) | B14: =B13/B7 -> 0.018959251
A15: Amount submitted excluding AMEX | B15: =B7-CardType!H7 -> 7301577.9 | C15: AMEX is funded and priced directly by American Express (Paid by Others)
A16: Fees excluding AMEX | B16: =B13+FeeSummary!D8 -> 170088.04 | C16: Only $170.00 of AMEX-related processor fees appear on this statement
A17: Effective rate excluding AMEX | B17: =B16/B15 -> 0.023294696
A18: Pass-through: interchange + card-brand assessments (IC/PF) | B18: =-FeeSummary!H6 -> 146436.8 | C18: Includes $9,965.45 of assessments/network fees and $3,863.23 of debit interchange (see FeeSummary)
A19: Pass-through share of total fees | B19: =B18/B13 -> 0.86008743
A20: Processor fees + service charges (markup) | B20: =-(FeeSummary!H5+FeeSummary!H7) -> 23821.24
A21: Markup share of total fees | B21: =B20/B13 -> 0.13991257
A22: Markup as % of volume excluding AMEX | B22: =B20/B15 -> 0.0032624784
A24: Effective rate by card brand
A25: Card brand | B25: Fees | C25: Net volume | D25: Effective rate | E25: Note
A26: Visa | B26: =-FeeSummary!B8 -> 86045.46 | C26: =CardType!H5 -> 4176165.4 | D26: =B26/C26 -> 0.02060394
A27: Mastercard | B27: =-FeeSummary!C8 -> 66487.73 | C27: =CardType!H4 -> 2580894 | D27: =B27/C27 -> 0.025761511
A28: Discover | B28: =-FeeSummary!E8 -> 3608.57 | C28: =CardType!H6 -> 151718.17 | D28: =B28/C28 -> 0.023784692
A29: Debit (PIN networks) | B29: =-FeeSummary!F8 -> 3898.1 | C29: =CardType!H8 -> 392800.35 | D29: =B29/C29 -> 0.009923871 | E29: Visa / Mastercard / Discover debit cards sit in their brand rows
A30: American Express | B30: =-FeeSummary!D8 -> 170 | C30: =CardType!H7 -> 1678631.3 | D30: =B30/C30 -> 0.00010127298 | E30: AMEX discount is billed by American Express, not on this statement
A31: Others (account-level, no brand) | B31: =-FeeSummary!G8 -> 10048.18 | E31: e.g. ANNUAL COMPLIANCE SVC FEE; counted in the total rate, not in any brand rate
A32: Total | B32: =SUM(B26:B31) -> 170258.04 | C32: =SUM(C26:C30) -> 8980209.2 | D32: =B32/C32 -> 0.018959251
A34: Largest individual fee lines (excluding IC/PF)
A35: Description (FeeDetail) | B35: Amount | C35: Product | D35: Type | E35: FeeDetail row
A36: =FeeDetail!D10 -> ANNUAL COMPLIANCE SVC FEE | B36: =-FeeDetail!F10 -> 6899.77 | C36: =FeeDetail!C10 -> Miscellaneous | D36: =FeeDetail!E10 -> Fees | E36: 10
A37: =FeeDetail!D195 -> VISA SALES DISCOUNT 0.0015 DISC RATE TIMES $2482035.50 | B37: =-FeeDetail!F195 -> 3723.04 | C37: =FeeDetail!C195 -> Visa | D37: =FeeDetail!E195 -> Service Charges | E37: 195
A38: =FeeDetail!D138 -> MASTERCARD SALES DISCOUNT 0.0015 DISC RATE TIMES $2051547.43 | B38: =-FeeDetail!F138 -> 3077.31 | C38: =FeeDetail!C138 -> Mastercard | D38: =FeeDetail!E138 -> Service Charges | E38: 138
A39: =FeeDetail!D190 -> VISA DEBIT SALES DISCOUNT 0.0015 DISC RATE TIMES $1826627.84 | B39: =-FeeDetail!F190 -> 2739.93 | C39: =FeeDetail!C190 -> Visa | D39: =FeeDetail!E190 -> Service Charges | E39: 190
A40: =FeeDetail!D21 -> VISA NETWORK FEE CNP 2-09 | B40: =-FeeDetail!F21 -> 1000.01 | C40: =FeeDetail!C21 -> Miscellaneous | D40: =FeeDetail!E21 -> Fees | E40: 21
A41: =FeeDetail!D146 -> MASTERCARD DEBIT SALES DISC 0.0015 DISC RATE TIMES $612749.80 | B41: =-FeeDetail!F146 -> 919.11 | C41: =FeeDetail!C146 -> Mastercard | D41: =FeeDetail!E146 -> Service Charges | E41: 146
A42: =FeeDetail!D122 -> CARDPOINTE PLATFORM FEE | B42: =-FeeDetail!F122 -> 803.85 | C42: =FeeDetail!C122 -> Miscellaneous | D42: =FeeDetail!E122 -> Service Charges | E42: 122
A43: =FeeDetail!D251 -> VISA AUTH FEE 5581 TRANSACTIONS AT 0.1 | B43: =-FeeDetail!F251 -> 558.1 | C43: =FeeDetail!C251 -> Visa | D43: =FeeDetail!E251 -> Fees | E43: 251
A44: =FeeDetail!D125 -> AVS WATS AUTHORIZATION FEE 10826 TRANSACTIONS AT 0.05 | B44: =-FeeDetail!F125 -> 541.3 | C44: =FeeDetail!C125 -> Miscellaneous | D44: =FeeDetail!E125 -> Fees | E44: 125
...

Sheet Trend
A1: 13 months sales trend (page 1 chart)
A2: Chart labels from the text layer; amounts are Amount Submitted per month.
A3: Month | B3: Amount Submitted | C3: Change vs previous month
A4: 45839 | B4: 3227208.9
A5: 45870 | B5: 3782196.9 | C5: =B5/B4-1 -> 0.17197151
A6: 45901 | B6: 4833175.6 | C6: =B6/B5-1 -> 0.2778752
A7: 45931 | B7: 6227957.9 | C7: =B7/B6-1 -> 0.28858505
A8: 45962 | B8: 5402522.7 | C8: =B8/B7-1 -> -0.13253705
A9: 45992 | B9: 5629409.6 | C9: =B9/B8-1 -> 0.041996477
A10: 46023 | B10: 4872899.1 | C10: =B10/B9-1 -> -0.13438541
A11: 46054 | B11: 4255217.5 | C11: =B11/B10-1 -> -0.12675855
A12: 46082 | B12: 4135241.7 | C12: =B12/B11-1 -> -0.02819498
A13: 46113 | B13: 5744885.9 | C13: =B13/B12-1 -> 0.38925034
A14: 46143 | B14: 7293127.3 | C14: =B14/B13-1 -> 0.26949906
A15: 46174 | B15: 8819730.6 | C15: =B15/B14-1 -> 0.20932081
A16: 46204 | B16: 8980209.2 | C16: =B16/B15-1 -> 0.018195405
A18: Jul 26 vs Jul 25 (year over year), computed | B18: =B16/B4-1 -> 1.782655
A19: Printed on page 1 | B19: =Summary!B29 -> 1.7827
A20: Jul 26 vs Jun 26 (month over month), computed | B20: =B16/B15-1 -> 0.018195405
A21: Printed on page 1 | B21: =Summary!B30 -> 0.0182

Sheet Checks
A1: Validation checks
A2: PASS = computed value equals the statement to the cent. REVIEW = differs (either a parse problem or a variance inside the source statement; see Findings).
A3: # | B3: Area | C3: Check | D3: Statement / expected | E3: Computed | F3: Difference | G3: Result
A4: 1 | B4: Summary | C4: Account summary: submitted + paid by others + disputes + adjustments + fees = amount processed | D4: =Summary!B21 -> 7130106 | E4: =Summary!B22 -> 7130106 | F4: =ROUND(E4-D4,2) -> 0 | G4: =IF(ABS(F4)<0.005,"PASS","REVIEW") -> PASS
A5: 2 | B5: Summary | C5: Average ticket = net submitted / net items | D5: =Summary!B27 -> 808.08 | E5: =Summary!B28 -> 808.08 | F5: =ROUND(E5-D5,2) -> 0 | G5: =IF(ABS(F5)<0.005,"PASS","REVIEW") -> PASS
A6: 3 | B6: Summary | C6: Locations included (page 1) = number of location rows | D6: =Summary!B9 -> 23 | E6: =COUNTA(Locations!A4:A26) -> 23 | F6: =ROUND(E6-D6,2) -> 0 | G6: =IF(ABS(F6)<0.005,"PASS","REVIEW") -> PASS
A7: 4 | B7: Trend | C7: Trend chart: Jul 26 value = Account Summary (Amount Submitted) | D7: =Summary!B16 -> 8980209.2 | E7: =Trend!B16 -> 8980209.2 | F7: =ROUND(E7-D7,2) -> 0 | G7: =IF(ABS(F7)<0.005,"PASS","REVIEW") -> PASS
A8: 5 | B8: Trend | C8: Trend chart: year over year (Jul 26 vs Jul 25), percent, printed vs recomputed | D8: =Summary!B29*100 -> 178.27 | E8: =ROUND(Trend!B18*100,2) -> 178.27 | F8: =ROUND(E8-D8,2) -> 0 | G8: =IF(ABS(F8)<0.005,"PASS","REVIEW") -> PASS
A9: 6 | B9: Trend | C9: Trend chart: month over month (Jun 26 vs Jul 26), percent, printed vs recomputed | D9: =Summary!B30*100 -> 1.82 | E9: =ROUND(Trend!B20*100,2) -> 1.82 | F9: =ROUND(E9-D9,2) -> 0 | G9: =IF(ABS(F9)<0.005,"PASS","REVIEW") -> PASS
A10: 7 | B10: Daily | C10: Summary By Day: sum of all rows incl. 06/30 and month-end = statement total (Amount Submitted) | D10: =Daily!B36 -> 8980209.2 | E10: =Daily!B37 -> 8980209.2 | F10: =ROUND(E10-D10,2) -> 0 | G10: =IF(ABS(F10)<0.005,"PASS","REVIEW") -> PASS
A11: 8 | B11: Daily | C11: Summary By Day: sum of all rows incl. 06/30 and month-end = statement total (Paid by Others) | D11: =Daily!C36 -> -1678631.3 | E11: =Daily!C37 -> -1678631.3 | F11: =ROUND(E11-D11,2) -> 0 | G11: =IF(ABS(F11)<0.005,"PASS","REVIEW") -> PASS
A12: 9 | B12: Daily | C12: Summary By Day: sum of all rows incl. 06/30 and month-end = statement total (Disputes) | D12: =Daily!D36 -> -1213.82 | E12: =Daily!D37 -> -1213.82 | F12: =ROUND(E12-D12,2) -> 0 | G12: =IF(ABS(F12)<0.005,"PASS","REVIEW") -> PASS
A13: 10 | B13: Daily | C13: Summary By Day: sum of all rows incl. 06/30 and month-end = statement total (Adjustments) | D13: =Daily!E36 -> 0 | E13: =Daily!E37 -> 0 | F13: =ROUND(E13-D13,2) -> 0 | G13: =IF(ABS(F13)<0.005,"PASS","REVIEW") -> PASS
A14: 11 | B14: Daily | C14: Summary By Day: sum of all rows incl. 06/30 and month-end = statement total (Fees) | D14: =Daily!F36 -> -170258.04 | E14: =Daily!F37 -> -170258.04 | F14: =ROUND(E14-D14,2) -> 0 | G14: =IF(ABS(F14)<0.005,"PASS","REVIEW") -> PASS
A15: 12 | B15: Daily | C15: Summary By Day: sum of all rows incl. 06/30 and month-end = statement total (Amount Processed) | D15: =Daily!G36 -> 7130106 | E15: =Daily!G37 -> 7130106 | F15: =ROUND(E15-D15,2) -> 0 | G15: =IF(ABS(F15)<0.005,"PASS","REVIEW") -> PASS
A16: 13 | B16: Daily | C16: Summary By Day total = Account Summary (Amount Submitted) | D16: =Summary!B16 -> 8980209.2 | E16: =Daily!B37 -> 8980209.2 | F16: =ROUND(E16-D16,2) -> 0 | G16: =IF(ABS(F16)<0.005,"PASS","REVIEW") -> PASS
A17: 14 | B17: Daily | C17: Summary By Day total = Account Summary (Amount Processed) | D17: =Summary!B21 -> 7130106 | E17: =Daily!G37 -> 7130106 | F17: =ROUND(E17-D17,2) -> 0 | G17: =IF(ABS(F17)<0.005,"PASS","REVIEW") -> PASS
A18: 15 | B18: Daily | C18: Each daily row: submitted + paid by others + disputes + adjustments + fees = processed (sum of absolute row errors) | D18: 0 | E18: =SUMPRODUCT(ABS(Daily!H4:H35)) -> 0 | F18: =ROUND(E18-D18,2) -> 0 | G18: =IF(ABS(F18)<0.005,"PASS","REVIEW") -> PASS
A19: 16 | B19: Daily | C19: Each date: Summary By Day amounts = sum of Amounts Funded rows for that submit date (sum of absolute differences) | D19: 0 | E19: =SUMPRODUCT(ABS(Daily!I4:I34)) -> 0 | F19: =ROUND(E19-D19,2) -> 0 | G19: =IF(ABS(F19)<0.005,"PASS","REVIEW") -> PASS
A20: 17 | B20: Daily | C20: Month End Charge = Account Summary fees | D20: =Summary!B20 -> -170258.04 | E20: =Daily!F35 -> -170258.04 | F20: =ROUND(E20-D20,2) -> 0 | G20: =IF(ABS(F20)<0.005,"PASS","REVIEW") -> PASS
A21: 18 | B21: Locations | C21: Summary By Location: sum of 23 rows = statement total (Amount Submitted) | D21: =Locations!B27 -> 8980209.2 | E21: =Locations!B28 -> 8980209.2 | F21: =ROUND(E21-D21,2) -> 0 | G21: =IF(ABS(F21)<0.005,"PASS","REVIEW") -> PASS
A22: 19 | B22: Locations | C22: Summary By Location: sum of 23 rows = statement total (Paid by Others) | D22: =Locations!C27 -> -1678631.3 | E22: =Locations!C28 -> -1678631.3 | F22: =ROUND(E22-D22,2) -> 0 | G22: =IF(ABS(F22)<0.005,"PASS","REVIEW") -> PASS
A23: 20 | B23: Locations | C23: Summary By Location: sum of 23 rows = statement total (Disputes) | D23: =Locations!D27 -> -1213.82 | E23: =Locations!D28 -> -1213.82 | F23: =ROUND(E23-D23,2) -> 0 | G23: =IF(ABS(F23)<0.005,"PASS","REVIEW") -> PASS
A24: 21 | B24: Locations | C24: Summary By Location: sum of 23 rows = statement total (Adjustments) | D24: =Locations!E27 -> 0 | E24: =Locations!E28 -> 0 | F24: =ROUND(E24-D24,2) -> 0 | G24: =IF(ABS(F24)<0.005,"PASS","REVIEW") -> PASS
A25: 22 | B25: Locations | C25: Summary By Location: sum of 23 rows = statement total (Fees) | D25: =Locations!F27 -> -170258.04 | E25: =Locations!F28 -> -170258.04 | F25: =ROUND(E25-D25,2) -> 0 | G25: =IF(ABS(F25)<0.005,"PASS","REVIEW") -> PASS
A26: 23 | B26: Locations | C26: Summary By Location: sum of 23 rows = statement total (Amount Processed) | D26: =Locations!G27 -> 7130106 | E26: =Locations!G28 -> 7130106 | F26: =ROUND(E26-D26,2) -> 0 | G26: =IF(ABS(F26)<0.005,"PASS","REVIEW") -> PASS
A27: 24 | B27: Locations | C27: Each location row: components add up to Processed Amount (sum of absolute row errors) | D27: 0 | E27: =SUMPRODUCT(ABS(Locations!H4:H26)) -> 0 | F27: =ROUND(E27-D27,2) -> 0 | G27: =IF(ABS(F27)<0.005,"PASS","REVIEW") -> PASS
A28: 25 | B28: Locations | C28: Location totals = Account Summary (Amount Processed) | D28: =Summary!B21 -> 7130106 | E28: =Locations!G28 -> 7130106 | F28: =ROUND(E28-D28,2) -> 0 | G28: =IF(ABS(F28)<0.005,"PASS","REVIEW") -> PASS
A29: 26 | B29: Paid by Others | C29: Paid by Others list: sum = statement total | D29: =PaidByOthers!C26 -> -1678631.3 | E29: =PaidByOthers!C27 -> -1678631.3 | F29: =ROUND(E29-D29,2) -> 0 | G29: =IF(ABS(F29)<0.005,"PASS","REVIEW") -> PASS
A30: 27 | B30: Paid by Others | C30: Paid by Others list per location = Summary By Location (sum of absolute differences) | D30: 0 | E30: =SUMPRODUCT(ABS(Locations!J4:J26)) -> 0 | F30: =ROUND(E30-D30,2) -> 0 | G30: =IF(ABS(F30)<0.005,"PASS","REVIEW") -> PASS
A31: 28 | B31: Paid by Others | C31: Paid by Others total = Account Summary | D31: =Summary!B17 -> -1678631.3 | E31: =PaidByOthers!C27 -> -1678631.3 | F31: =ROUND(E31-D31,2) -> 0 | G31: =IF(ABS(F31)<0.005,"PASS","REVIEW") -> PASS
A32: 29 | B32: Card type | C32: Each card row: gross + refunds = net amount (sum of absolute row errors) | D32: 0 | E32: =SUMPRODUCT(ABS(CardType!I4:I8)) -> 0 | F32: =ROUND(E32-D32,2) -> 0 | G32: =IF(ABS(F32)<0.005,"PASS","REVIEW") -> PASS
A33: 30 | B33: Card type | C33: Each card row: gross items + refund items = total items (sum of absolute row errors) | D33: 0 | E33: =SUMPRODUCT(ABS(CardType!J4:J8)) -> 0 | F33: =ROUND(E33-D33,2) -> 0 | G33: =IF(ABS(F33)<0.005,"PASS","REVIEW") -> PASS
A34: 31 | B34: Card type | C34: Card type totals: sum of rows = statement total (gross items) | D34: =CardType!C9 -> 10571 | E34: =CardType!C10 -> 10571 | F34: =ROUND(E34-D34,2) -> 0 | G34: =IF(ABS(F34)<0.005,"PASS","REVIEW") -> PASS
A35: 32 | B35: Card type | C35: Card type totals: sum of rows = statement total (gross sales) | D35: =CardType!D9 -> 9228078.2 | E35: =CardType!D10 -> 9228078.2 | F35: =ROUND(E35-D35,2) -> 0 | G35: =IF(ABS(F35)<0.005,"PASS","REVIEW") -> PASS
A36: 33 | B36: Card type | C36: Card type totals: sum of rows = statement total (refund items) | D36: =CardType!E9 -> 542 | E36: =CardType!E10 -> 542 | F36: =ROUND(E36-D36,2) -> 0 | G36: =IF(ABS(F36)<0.005,"PASS","REVIEW") -> PASS
A37: 34 | B37: Card type | C37: Card type totals: sum of rows = statement total (refunds) | D37: =CardType!F9 -> -247869 | E37: =CardType!F10 -> -247869 | F37: =ROUND(E37-D37,2) -> 0 | G37: =IF(ABS(F37)<0.005,"PASS","REVIEW") -> PASS
A38: 35 | B38: Card type | C38: Card type totals: sum of rows = statement total (total items) | D38: =CardType!G9 -> 11113 | E38: =CardType!G10 -> 11113 | F38: =ROUND(E38-D38,2) -> 0 | G38: =IF(ABS(F38)<0.005,"PASS","REVIEW") -> PASS
A39: 36 | B39: Card type | C39: Card type totals: sum of rows = statement total (net amount) | D39: =CardType!H9 -> 8980209.2 | E39: =CardType!H10 -> 8980209.2 | F39: =ROUND(E39-D39,2) -> 0 | G39: =IF(ABS(F39)<0.005,"PASS","REVIEW") -> PASS
A40: 37 | B40: Card type | C40: Card type net total = Account Summary (Amount Submitted) | D40: =Summary!B16 -> 8980209.2 | E40: =CardType!H10 -> 8980209.2 | F40: =ROUND(E40-D40,2) -> 0 | G40: =IF(ABS(F40)<0.005,"PASS","REVIEW") -> PASS
...

Sheet Findings
A1: Findings: parsing hazards and source-statement variances
A3: # | B3: Type | C3: Area | D3: Finding | E3: Why it matters for parsing | F3: Suggested handling
A4: 1 | B4: Parse hazard | C4: Summary By Day | D4: The July statement includes a 06/30/2026 row ($509,561.75 submitted) and its amounts are inside the statement totals. There is also an undated "Month End Charge" row and a "Total" row. | E4: A filter on the statement period drops 06/30 and the daily table then no longer sums to the printed total. | F4: Do not filter by period; treat Month End Charge and Total as separate row types.
A5: 2 | B5: Parse hazard | C5: Summary By Day | D5: No row for 07/26/2026 (Sunday): days without activity are omitted, not shown as zero. | E5: A date-indexed load will have a gap; the day is only visible in Amounts Funded (funded 07/26). | F5: Reindex to the full calendar and fill zeros if a continuous series is needed.
A6: 3 | B6: Parse hazard | C6: Fee lines | D6: Category and Product are printed only on the first row of each group and change mid-list (Miscellaneous, Mastercard, Visa, Discover, Amex, Debit); headers repeat after every page break. | E6: Rows after the first in a group have no category/product in the text. | F6: Forward-fill Category and Product; drop repeated header lines.
A7: 4 | B7: Parse hazard | C7: Fee lines / Interchange | D7: Duplicate key: "VI-US BUS TIER 5 PRD 1 CEDP" appears twice in the Visa interchange table ($22,095.20 at 2.25% and $228,931.31 at 3.00%) and twice in the fee list. | E7: Keying or joining on description alone merges two different rows. | F7: Use brand + description + rate (or row order) as the key.
A8: 5 | B8: Parse hazard | C8: Fee lines | D8: The Type column labels assessment fees (Mastercard, Visa credit/debit, Discover) and one Mastercard network settlement fee as "Interchange Charges" (total $9,965.45). | E8: Type-based totals will not match the interchange table. | F8: Keep the printed Type, add a derived class if a true interchange split is needed.
A9: 6 | B9: Parse hazard | C9: Fee Summary vs Interchange table | D9: IC/PF on the Fee Summary is $146,436.80 but the interchange table totals $132,608.12. Difference $13,828.68 = assessments/network fees $9,965.45 + debit interchange $3,863.23. | E9: The interchange table shows $0.00 for every debit network while the fee list charges $3,863.23 of debit interchange. | F9: Reconcile with the bridge on the FeeSummary sheet; the parse itself is complete.
A10: 7 | B10: Parse hazard | C10: Amounts Funded | D10: Funded fees are -$163,012.13 versus a Month End Charge of -$170,258.04; Amount Funded total $7,137,351.92 versus Amount Processed $7,130,106.01 (difference $7,245.91). | E10: Funding does not reconcile to Amount Processed by design (funded fees come from the prior statement). | F10: Reconcile with the check on the Checks sheet.
A11: 8 | B11: Parse hazard | C11: Page 1 header | D11: Page 1 visibly shows "ABC Company" and "DOWNINGTOWN PA 19335" with the corporate number cut to "4961". The text layer contains extra text behind the overlay: a different company name, a contact name and a street address (a redaction done by covering text, not removing it). The six summary amounts and the 13 monthly values also come out of label order, and each month label is split over several lines ("Jul / 25 / - / $3,227,208.93"). | E11: A text-based parser returns the hidden values, an OCR or visual parser returns the visible ones, so the same statement gives two different merchants. The sample also exposes identifying data of what looks like a real merchant. | F11: Decide which layer is authoritative; map summary amounts by the equation and by the Total rows; take the corporate number from the first Location ID in Summary By Location on page 3 (the page headers visibly show only 4961; the full number there sits in the text layer). Consider telling the sender that the PDF still carries the underlying text.
A12: 9 | B12: Parse hazard | C12: Interchange table | D12: The printed "% of Sales" uses the sum of absolute sales of the brand as denominator (refund lines count as positive), not the net Sales Total shown in the brand total. Example: VI-US REGULATED COMM (DB) prints 24% although $1,085,708.06 / $4,176,165.36 = 26%; refund lines print positive percentages. % of Transactions uses the brand transaction total. | E12: Recomputing percentages from the net brand total gives values that do not match the printed ones. | F12: Recompute with the absolute basis (columns M-O of the Interchange sheet: all 140 lines tie).
A13: 10 | B13: Parse hazard | C13: Sign and formatting | D13: Negative values are printed "-$1,234.56"; refunds, Paid by Others, disputes and fees are negative; one positive Paid by Others value (+$20.34) appears on 07/15 in Amounts Funded; percentages are rounded and the % columns are not exact. | E13: Stripping "$" and "," without handling the leading minus, or taking absolute values, changes totals. | F13: Parse sign explicitly; recompute percentages instead of storing the printed ones.
A14: 11 | B14: Parse hazard | C14: Card Type | D14: The Debit row (653 items, $392,800.35) covers PIN-debit networks only; Visa, Mastercard and Discover rows already include their own debit cards. The five rows add up to the net total, but the fee list splits debit differently (e.g. VISA DEBIT SALES DISCOUNT sits under Visa; the Debit product carries network and ILK fees). | E14: Mapping fee lines to card-type rows by the word "debit" gives wrong brand attribution. | F14: Attribute fee lines by the Product printed in the fee list, not by description keywords.
A15: 12 | B15: Source variance | C15: Interchange | D15: VI-US BUS TR4 PRD 3: printed charge -$358.79 vs $330.37 from 2.70% x $12,191.53 + 12 x $0.10 (difference $28.42). It matches the fee list, so the parse is faithful. | E15: Effective rate implied by the charge is about 2.93% versus the printed 2.70%. | F15: Ask the processor or confirm the rate table; flag rather than correct.
... A18: 15 | B18: Info | C18: Rounding | D18: 62 interchange lines differ from rate x sales + txns x fee by $0.01 to $0.04 (printed rates are rounded to 4 decimals). 26 fee lines differ from basis x rate by $0.01 to $0.10; the largest are two "VI DIGTL COM US CNP SVC FEE MN" lines (5 and 10 transactions) charged $0.05 and $0.10 more than transactions x rate. The statement does not state the reason. | E18: Do not treat differences of a few cents per line as parse errors. | F18: Tolerances used: $0.05 on the Interchange sheet and $0.11 on FeeDetail.
A19: 16 | B19: Info | C19: Not parsed | D19: The compliance notice after page 16 is boilerplate with no data. The printed YoY (178.27%) and MoM (1.82%) are rounded and are recomputed on the Trend sheet. | F19: None needed.

Sheet Daily
A1: Summary By Day
A2: Note: the table includes a 06/30/2026 row (previous month) and its amounts are inside the statement totals. No row exists for 07/26/2026.
A3: Date | B3: Amount Submitted | C3: Paid by Others | D3: Disputes | E3: Adjustments | F3: Fees | G3: Amount Processed | H3: Row check (should be 0) | I3: Funded tie-out (should be 0)
A4: 46203 | B4: 509561.75 | C4: -118230.89 | D4: 0 | E4: 0 | F4: 0 | G4: 391330.86 | H4: =ROUND(SUM(B4:F4)-G4,2) -> 0 | I4: =ROUND(ABS(SUMIFS(Funded!$B$4:$B$57,Funded!$A$4:$A$57,$A4)-B4)+ABS(SUMIFS(Funded!$C$4:$C$57,Funded!$A$4:$A$57,$A4)-C4)+ABS(SUMIFS(Funded!$D$4:$D$57,Funded!$A$4:$A$57,$A4)-D4)+ABS(SUMIFS(Funded!$E$4:$E$57,Funded!$A$4:$A$57,$A4)-E4),2) -> 0
A5: 46204 | B5: 420610.31 | C5: -55478.76 | D5: -1213.82 | E5: 0 | F5: 0 | G5: 363917.73 | H5: =ROUND(SUM(B5:F5)-G5,2) -> 0 | I5: =ROUND(ABS(SUMIFS(Funded!$B$4:$B$57,Funded!$A$4:$A$57,$A5)-B5)+ABS(SUMIFS(Funded!$C$4:$C$57,Funded!$A$4:$A$57,$A5)-C5)+ABS(SUMIFS(Funded!$D$4:$D$57,Funded!$A$4:$A$57,$A5)-D5)+ABS(SUMIFS(Funded!$E$4:$E$57,Funded!$A$4:$A$57,$A5)-E5),2) -> 0
A6: 46205 | B6: 475682.04 | C6: -97077.08 | D6: 0 | E6: 0 | F6: 0 | G6: 378604.96 | H6: =ROUND(SUM(B6:F6)-G6,2) -> 0 | I6: =ROUND(ABS(SUMIFS(Funded!$B$4:$B$57,Funded!$A$4:$A$57,$A6)-B6)+ABS(SUMIFS(Funded!$C$4:$C$57,Funded!$A$4:$A$57,$A6)-C6)+ABS(SUMIFS(Funded!$D$4:$D$57,Funded!$A$4:$A$57,$A6)-D6)+ABS(SUMIFS(Funded!$E$4:$E$57,Funded!$A$4:$A$57,$A6)-E6),2) -> 0
A7: 46206 | B7: 136800.78 | C7: -21544.12 | D7: 0 | E7: 0 | F7: 0 | G7: 115256.66 | H7: =ROUND(SUM(B7:F7)-G7,2) -> 0 | I7: =ROUND(ABS(SUMIFS(Funded!$B$4:$B$57,Funded!$A$4:$A$57,$A7)-B7)+ABS(SUMIFS(Funded!$C$4:$C$57,Funded!$A$4:$A$57,$A7)-C7)+ABS(SUMIFS(Funded!$D$4:$D$57,Funded!$A$4:$A$57,$A7)-D7)+ABS(SUMIFS(Funded!$E$4:$E$57,Funded!$A$4:$A$57,$A7)-E7),2) -> 0
A8: 46207 | B8: -395.25 | C8: -1965.52 | D8: 0 | E8: 0 | F8: 0 | G8: -2360.77 | H8: =ROUND(SUM(B8:F8)-G8,2) -> 0 | I8: =ROUND(ABS(SUMIFS(Funded!$B$4:$B$57,Funded!$A$4:$A$57,$A8)-B8)+ABS(SUMIFS(Funded!$C$4:$C$57,Funded!$A$4:$A$57,$A8)-C8)+ABS(SUMIFS(Funded!$D$4:$D$57,Funded!$A$4:$A$57,$A8)-D8)+ABS(SUMIFS(Funded!$E$4:$E$57,Funded!$A$4:$A$57,$A8)-E8),2) -> 0
A9: 46208 | B9: 1818.92 | C9: 0 | D9: 0 | E9: 0 | F9: 0 | G9: 1818.92 | H9: =ROUND(SUM(B9:F9)-G9,2) -> 0 | I9: =ROUND(ABS(SUMIFS(Funded!$B$4:$B$57,Funded!$A$4:$A$57,$A9)-B9)+ABS(SUMIFS(Funded!$C$4:$C$57,Funded!$A$4:$A$57,$A9)-C9)+ABS(SUMIFS(Funded!$D$4:$D$57,Funded!$A$4:$A$57,$A9)-D9)+ABS(SUMIFS(Funded!$E$4:$E$57,Funded!$A$4:$A$57,$A9)-E9),2) -> 0
A10: 46209 | B10: 368117.09 | C10: -63882.42 | D10: 0 | E10: 0 | F10: 0 | G10: 304234.67 | H10: =ROUND(SUM(B10:F10)-G10,2) -> 0 | I10: =ROUND(ABS(SUMIFS(Funded!$B$4:$B$57,Funded!$A$4:$A$57,$A10)-B10)+ABS(SUMIFS(Funded!$C$4:$C$57,Funded!$A$4:$A$57,$A10)-C10)+ABS(SUMIFS(Funded!$D$4:$D$57,Funded!$A$4:$A$57,$A10)-D10)+ABS(SUMIFS(Funded!$E$4:$E$57,Funded!$A$4:$A$57,$A10)-E10),2) -> 0
A11: 46210 | B11: 428727.25 | C11: -89809.19 | D11: 0 | E11: 0 | F11: 0 | G11: 338918.06 | H11: =ROUND(SUM(B11:F11)-G11,2) -> 0 | I11: =ROUND(ABS(SUMIFS(Funded!$B$4:$B$57,Funded!$A$4:$A$57,$A11)-B11)+ABS(SUMIFS(Funded!$C$4:$C$57,Funded!$A$4:$A$57,$A11)-C11)+ABS(SUMIFS(Funded!$D$4:$D$57,Funded!$A$4:$A$57,$A11)-D11)+ABS(SUMIFS(Funded!$E$4:$E$57,Funded!$A$4:$A$57,$A11)-E11),2) -> 0
A12: 46211 | B12: 452197.88 | C12: -76864.6 | D12: 0 | E12: 0 | F12: 0 | G12: 375333.28 | H12: =ROUND(SUM(B12:F12)-G12,2) -> 0 | I12: =ROUND(ABS(SUMIFS(Funded!$B$4:$B$57,Funded!$A$4:$A$57,$A12)-B12)+ABS(SUMIFS(Funded!$C$4:$C$57,Funded!$A$4:$A$57,$A12)-C12)+ABS(SUMIFS(Funded!$D$4:$D$57,Funded!$A$4:$A$57,$A12)-D12)+ABS(SUMIFS(Funded!$E$4:$E$57,Funded!$A$4:$A$57,$A12)-E12),2) -> 0
A13: 46212 | B13: 481718.91 | C13: -61209.25 | D13: 0 | E13: 0 | F13: 0 | G13: 420509.66 | H13: =ROUND(SUM(B13:F13)-G13,2) -> 0 | I13: =ROUND(ABS(SUMIFS(Funded!$B$4:$B$57,Funded!$A$4:$A$57,$A13)-B13)+ABS(SUMIFS(Funded!$C$4:$C$57,Funded!$A$4:$A$57,$A13)-C13)+ABS(SUMIFS(Funded!$D$4:$D$57,Funded!$A$4:$A$57,$A13)-D13)+ABS(SUMIFS(Funded!$E$4:$E$57,Funded!$A$4:$A$57,$A13)-E13),2) -> 0
A14: 46213 | B14: 465171.68 | C14: -71684.68 | D14: 0 | E14: 0 | F14: 0 | G14: 393487 | H14: =ROUND(SUM(B14:F14)-G14,2) -> 0 | I14: =ROUND(ABS(SUMIFS(Funded!$B$4:$B$57,Funded!$A$4:$A$57,$A14)-B14)+ABS(SUMIFS(Funded!$C$4:$C$57,Funded!$A$4:$A$57,$A14)-C14)+ABS(SUMIFS(Funded!$D$4:$D$57,Funded!$A$4:$A$57,$A14)-D14)+ABS(SUMIFS(Funded!$E$4:$E$57,Funded!$A$4:$A$57,$A14)-E14),2) -> 0
A15: 46214 | B15: 17460.37 | C15: -1472.36 | D15: 0 | E15: 0 | F15: 0 | G15: 15988.01 | H15: =ROUND(SUM(B15:F15)-G15,2) -> 0 | I15: =ROUND(ABS(SUMIFS(Funded!$B$4:$B$57,Funded!$A$4:$A$57,$A15)-B15)+ABS(SUMIFS(Funded!$C$4:$C$57,Funded!$A$4:$A$57,$A15)-C15)+ABS(SUMIFS(Funded!$D$4:$D$57,Funded!$A$4:$A$57,$A15)-D15)+ABS(SUMIFS(Funded!$E$4:$E$57,Funded!$A$4:$A$57,$A15)-E15),2) -> 0
... A34: 46234 | B34: 6679.24 | C34: -2466.5 | D34: 0 | E34: 0 | F34: 0 | G34: 4212.74 | H34: =ROUND(SUM(B34:F34)-G34,2) -> 0 | I34: =ROUND(ABS(SUMIFS(Funded!$B$4:$B$57,Funded!$A$4:$A$57,$A34)-B34)+ABS(SUMIFS(Funded!$C$4:$C$57,Funded!$A$4:$A$57,$A34)-C34)+ABS(SUMIFS(Funded!$D$4:$D$57,Funded!$A$4:$A$57,$A34)-D34)+ABS(SUMIFS(Funded!$E$4:$E$57,Funded!$A$4:$A$57,$A34)-E34),2) -> 0
A35: Month End Charge | B35: 0 | C35: 0 | D35: 0 | E35: 0 | F35: -170258.04 | G35: -170258.04 | H35: =ROUND(SUM(B35:F35)-G35,2) -> 0
A36: Total (statement) | B36: 8980209.2 | C36: -1678631.3 | D36: -1213.82 | E36: 0 | F36: -170258.04 | G36: 7130106
A37: Total (computed) | B37: =SUM(B4:B35) -> 8980209.2 | C37: =SUM(C4:C35) -> -1678631.3 | D37: =SUM(D4:D35) -> -1213.82 | E37: =SUM(E4:E35) -> 0 | F37: =SUM(F4:F35) -> -170258.04 | G37: =SUM(G4:G35) -> 7130106
A38: Difference | B38: =ROUND(B37-B36,2) -> 0 | C38: =ROUND(C37-C36,2) -> 0 | D38: =ROUND(D37-D36,2) -> 0 | E38: =ROUND(E37-E36,2) -> 0 | F38: =ROUND(F37-F36,2) -> 0 | G38: =ROUND(G37-G36,2) -> 0

Sheet CardType
A1: Summary by Card Type
A2: Average ticket on the statement is net amount / net items (refund items count as items).
A3: Card Type | B3: Average Ticket (statement) | C3: Gross Items | D3: Gross Sales Amount | E3: Refund Items | F3: Refund Amount | G3: Total Items | H3: Total Amount Submitted | I3: Check: gross + refunds - net | J3: Check: items | K3: Avg ticket (computed) | L3: Avg ticket diff | M3: Share of net | N3: Share printed (pie chart, page 3) | O3: Printed vs recomputed (4 dp)
A4: MASTERCARD | B4: 786.14 | C4: 3093 | D4: 2664297.2 | E4: 190 | F4: -83403.24 | G4: 3283 | H4: 2580894 | I4: =ROUND(D4+F4-H4,2) -> 0 | J4: =C4+E4-G4 -> 0 | K4: =ROUND(H4/G4,2) -> 786.14 | L4: =ROUND(K4-B4,2) -> 0 | M4: =H4/$H$9 -> 0.28739798 | N4: 0.2874 | O4: =ROUND(M4,4)-N4 -> 0
A5: VISA | B5: 782.05 | C5: 5065 | D5: 4308663.3 | E5: 275 | F5: -132497.98 | G5: 5340 | H5: 4176165.4 | I5: =ROUND(D5+F5-H5,2) -> 0 | J5: =C5+E5-G5 -> 0 | K5: =ROUND(H5/G5,2) -> 782.05 | L5: =ROUND(K5-B5,2) -> 0 | M5: =H5/$H$9 -> 0.46504099 | N5: 0.465 | O5: =ROUND(M5,4)-N5 -> 0
A6: DISCOVER | B6: 751.08 | C6: 192 | D6: 154076.77 | E6: 10 | F6: -2358.6 | G6: 202 | H6: 151718.17 | I6: =ROUND(D6+F6-H6,2) -> 0 | J6: =C6+E6-G6 -> 0 | K6: =ROUND(H6/G6,2) -> 751.08 | L6: =ROUND(K6-B6,2) -> 0 | M6: =H6/$H$9 -> 0.016894726 | N6: 0.0169 | O6: =ROUND(M6,4)-N6 -> 0
A7: AMERICAN EXPRESS | B7: 1026.69 | C7: 1568 | D7: 1708240.5 | E7: 67 | F7: -29609.18 | G7: 1635 | H7: 1678631.3 | I7: =ROUND(D7+F7-H7,2) -> 0 | J7: =C7+E7-G7 -> 0 | K7: =ROUND(H7/G7,2) -> 1026.69 | L7: =ROUND(K7-B7,2) -> 0 | M7: =H7/$H$9 -> 0.18692564 | N7: 0.1869 | O7: =ROUND(M7,4)-N7 -> 0
A8: DEBIT CARD | B8: 601.53 | C8: 653 | D8: 392800.35 | E8: 0 | F8: 0 | G8: 653 | H8: 392800.35 | I8: =ROUND(D8+F8-H8,2) -> 0 | J8: =C8+E8-G8 -> 0 | K8: =ROUND(H8/G8,2) -> 601.53 | L8: =ROUND(K8-B8,2) -> 0 | M8: =H8/$H$9 -> 0.043740668 | N8: 0.0437 | O8: =ROUND(M8,4)-N8 -> 0
A9: Total (statement) | C9: 10571 | D9: 9228078.2 | E9: 542 | F9: -247869 | G9: 11113 | H9: 8980209.2
A10: Total (computed) | C10: =SUM(C4:C8) -> 10571 | D10: =SUM(D4:D8) -> 9228078.2 | E10: =SUM(E4:E8) -> 542 | F10: =SUM(F4:F8) -> -247869 | G10: =SUM(G4:G8) -> 11113 | H10: =SUM(H4:H8) -> 8980209.2 | K10: =ROUND(H10/G10,2) -> 808.08
A11: Difference | C11: =ROUND(C10-C9,2) -> 0 | D11: =ROUND(D10-D9,2) -> 0 | E11: =ROUND(E10-E9,2) -> 0 | F11: =ROUND(F10-F9,2) -> 0 | G11: =ROUND(G10-G9,2) -> 0 | H11: =ROUND(H10-H9,2) -> 0

Sheet Locations
A1: Summary By Location (23 locations)
A3: Location ID | B3: Amount Submitted | C3: Paid by Others | D3: Disputes | E3: Adjustments | F3: Fees | G3: Processed Amount | H3: Row check | I3: Paid by Others per list | J3: PBO diff
A4: 496115385882 | B4: 663551.51 | C4: -112170.62 | D4: 0 | E4: 0 | F4: -16503.2 | G4: 534877.69 | H4: =ROUND(SUM(B4:F4)-G4,2) -> 0 | I4: =SUMPRODUCT((PaidByOthers!$A$4:$A$25=A4)*PaidByOthers!$C$4:$C$25) -> -112170.62 | J4: =ROUND(I4-C4,2) -> 0
A5: 496116308883 | B5: 450527.16 | C5: -72683.76 | D5: 0 | E5: 0 | F5: -8658.04 | G5: 369185.36 | H5: =ROUND(SUM(B5:F5)-G5,2) -> 0 | I5: =SUMPRODUCT((PaidByOthers!$A$4:$A$25=A5)*PaidByOthers!$C$4:$C$25) -> -72683.76 | J5: =ROUND(I5-C5,2) -> 0
A6: 496116313883 | B6: 278189.09 | C6: -21775.01 | D6: 0 | E6: 0 | F6: -6788.13 | G6: 249625.95 | H6: =ROUND(SUM(B6:F6)-G6,2) -> 0 | I6: =SUMPRODUCT((PaidByOthers!$A$4:$A$25=A6)*PaidByOthers!$C$4:$C$25) -> -21775.01 | J6: =ROUND(I6-C6,2) -> 0
A7: 496116314881 | B7: 278226.06 | C7: -40102.29 | D7: 0 | E7: 0 | F7: -6054.24 | G7: 232069.53 | H7: =ROUND(SUM(B7:F7)-G7,2) -> 0 | I7: =SUMPRODUCT((PaidByOthers!$A$4:$A$25=A7)*PaidByOthers!$C$4:$C$25) -> -40102.29 | J7: =ROUND(I7-C7,2) -> 0
A8: 496116316886 | B8: 1251729.6 | C8: -305584.22 | D8: 0 | E8: 0 | F8: -20760.07 | G8: 925385.29 | H8: =ROUND(SUM(B8:F8)-G8,2) -> 0 | I8: =SUMPRODUCT((PaidByOthers!$A$4:$A$25=A8)*PaidByOthers!$C$4:$C$25) -> -305584.22 | J8: =ROUND(I8-C8,2) -> 0
A9: 496116317884 | B9: 421779.8 | C9: -43230.27 | D9: 0 | E9: 0 | F9: -7325.32 | G9: 371224.21 | H9: =ROUND(SUM(B9:F9)-G9,2) -> 0 | I9: =SUMPRODUCT((PaidByOthers!$A$4:$A$25=A9)*PaidByOthers!$C$4:$C$25) -> -43230.27 | J9: =ROUND(I9-C9,2) -> 0
A10: 496116318882 | B10: 423642.31 | C10: -36882.61 | D10: 0 | E10: 0 | F10: -12149.34 | G10: 374610.36 | H10: =ROUND(SUM(B10:F10)-G10,2) -> 0 | I10: =SUMPRODUCT((PaidByOthers!$A$4:$A$25=A10)*PaidByOthers!$C$4:$C$25) -> -36882.61 | J10: =ROUND(I10-C10,2) -> 0
A11: 496116319880 | B11: 449308.19 | C11: -60986.13 | D11: 0 | E11: 0 | F11: -7364.64 | G11: 380957.42 | H11: =ROUND(SUM(B11:F11)-G11,2) -> 0 | I11: =SUMPRODUCT((PaidByOthers!$A$4:$A$25=A11)*PaidByOthers!$C$4:$C$25) -> -60986.13 | J11: =ROUND(I11-C11,2) -> 0
A12: 496116321886 | B12: 131235.71 | C12: -18657.54 | D12: 0 | E12: 0 | F12: -2954.97 | G12: 109623.2 | H12: =ROUND(SUM(B12:F12)-G12,2) -> 0 | I12: =SUMPRODUCT((PaidByOthers!$A$4:$A$25=A12)*PaidByOthers!$C$4:$C$25) -> -18657.54 | J12: =ROUND(I12-C12,2) -> 0
A13: 496116322884 | B13: 649816.1 | C13: -330284.41 | D13: 0 | E13: 0 | F13: -6627.81 | G13: 312903.88 | H13: =ROUND(SUM(B13:F13)-G13,2) -> 0 | I13: =SUMPRODUCT((PaidByOthers!$A$4:$A$25=A13)*PaidByOthers!$C$4:$C$25) -> -330284.41 | J13: =ROUND(I13-C13,2) -> 0
A14: 496116323882 | B14: 335103.31 | C14: -20629.27 | D14: 0 | E14: 0 | F14: -7790.56 | G14: 306683.48 | H14: =ROUND(SUM(B14:F14)-G14,2) -> 0 | I14: =SUMPRODUCT((PaidByOthers!$A$4:$A$25=A14)*PaidByOthers!$C$4:$C$25) -> -20629.27 | J14: =ROUND(I14-C14,2) -> 0
A15: 496116325887 | B15: 159370.32 | C15: -11748.84 | D15: 0 | E15: 0 | F15: -2644.64 | G15: 144976.84 | H15: =ROUND(SUM(B15:F15)-G15,2) -> 0 | I15: =SUMPRODUCT((PaidByOthers!$A$4:$A$25=A15)*PaidByOthers!$C$4:$C$25) -> -11748.84 | J15: =ROUND(I15-C15,2) -> 0
... A26: 496613745884 | B26: 9086.15 | C26: -1559.3 | D26: 0 | E26: 0 | F26: -509.25 | G26: 7017.6 | H26: =ROUND(SUM(B26:F26)-G26,2) -> 0 | I26: =SUMPRODUCT((PaidByOthers!$A$4:$A$25=A26)*PaidByOthers!$C$4:$C$25) -> -1559.3 | J26: =ROUND(I26-C26,2) -> 0
A27: Total (statement) | B27: 8980209.2 | C27: -1678631.3 | D27: -1213.82 | E27: 0 | F27: -170258.04 | G27: 7130106
A28: Total (computed) | B28: =SUM(B4:B26) -> 8980209.2 | C28: =SUM(C4:C26) -> -1678631.3 | D28: =SUM(D4:D26) -> -1213.82 | E28: =SUM(E4:E26) -> 0 | F28: =SUM(F4:F26) -> -170258.04 | G28: =SUM(G4:G26) -> 7130106
A29: Difference | B29: =ROUND(B28-B27,2) -> 0 | C29: =ROUND(C28-C27,2) -> 0 | D29: =ROUND(D28-D27,2) -> 0 | E29: =ROUND(E28-E27,2) -> 0 | F29: =ROUND(F28-F27,2) -> 0 | G29: =ROUND(G28-G27,2) -> 0

Sheet PaidByOthers
A1: Paid by Others
A2: Transactions passed directly to the card association for processing and funding (American Express).
A3: Location ID | B3: Description | C3: Amount
A4: 496115385882 | B4: Transactions submitted to American Express | C4: -112170.62
A5: 496116308883 | B5: Transactions submitted to American Express | C5: -72683.76
A6: 496116313883 | B6: Transactions submitted to American Express | C6: -21775.01
A7: 496116314881 | B7: Transactions submitted to American Express | C7: -40102.29
A8: 496116316886 | B8: Transactions submitted to American Express | C8: -305584.22
A9: 496116317884 | B9: Transactions submitted to American Express | C9: -43230.27
A10: 496116318882 | B10: Transactions submitted to American Express | C10: -36882.61
A11: 496116319880 | B11: Transactions submitted to American Express | C11: -60986.13
A12: 496116321886 | B12: Transactions submitted to American Express | C12: -18657.54
A13: 496116322884 | B13: Transactions submitted to American Express | C13: -330284.41
A14: 496116323882 | B14: Transactions submitted to American Express | C14: -20629.27
A15: 496116325887 | B15: Transactions submitted to American Express | C15: -11748.84
... A25: 496613745884 | B25: Transactions submitted to American Express | C25: -1559.3
A26: Total (statement) | C26: -1678631.3
A27: Total (computed) | C27: =SUM(C4:C25) -> -1678631.3

Sheet Disputes
A1: Disputes
A3: Location ID | B3: Date | C3: Reference No. | D3: Description | E3: Card number (last 4) | F3: Amount
A4: 496116335886 | B4: 46204 | C4: 861813362701 | D4: Cardholder disputing service/merchandise | E4: 9127 | F4: -1213.82
A5: Total Credits | F5: 0
A6: Total Debits | F6: =SUM(F4:F4) -> -1213.82
A7: Net disputes | F7: =F5+F6 -> -1213.82

Sheet FeeSummary
A1: Fee summary and reconciliations
A3: Fee matrix as printed (page 4)
B4: Visa | C4: Mastercard | D4: Amex | E4: Discover | F4: Debit | G4: Others | H4: Total
A5: Fees | B5: -1759.72 | C5: -966.12 | D5: -170 | E5: -25.61 | F5: -2.74 | G5: -9209.44 | H5: -12133.63
A6: Interchange Charges | B6: -77822.77 | C6: -61395.78 | D6: 0 | E6: -3351.3 | F6: -3863.23 | G6: -3.72 | H6: -146436.8
A7: Service Charges | B7: -6462.97 | C7: -4125.83 | D7: 0 | E7: -231.66 | F7: -32.13 | G7: -835.02 | H7: -11687.61
A8: Total | B8: -86045.46 | C8: -66487.73 | D8: -170 | E8: -3608.57 | F8: -3898.1 | G8: -10048.18 | H8: -170258.04
A10: Recomputed from FeeDetail (Others = Miscellaneous)
A11: Type / Product | B11: Visa | C11: Mastercard | D11: Amex | E11: Discover | F11: Debit | G11: Miscellaneous | H11: Total
A12: Fees | B12: =SUMIFS(FeeDetail!$F$4:$F$360,FeeDetail!$E$4:$E$360,$A12,FeeDetail!$C$4:$C$360,B$11) -> -1759.72 | C12: =SUMIFS(FeeDetail!$F$4:$F$360,FeeDetail!$E$4:$E$360,$A12,FeeDetail!$C$4:$C$360,C$11) -> -966.12 | D12: =SUMIFS(FeeDetail!$F$4:$F$360,FeeDetail!$E$4:$E$360,$A12,FeeDetail!$C$4:$C$360,D$11) -> -170 | E12: =SUMIFS(FeeDetail!$F$4:$F$360,FeeDetail!$E$4:$E$360,$A12,FeeDetail!$C$4:$C$360,E$11) -> -25.61 | F12: =SUMIFS(FeeDetail!$F$4:$F$360,FeeDetail!$E$4:$E$360,$A12,FeeDetail!$C$4:$C$360,F$11) -> -2.74 | G12: =SUMIFS(FeeDetail!$F$4:$F$360,FeeDetail!$E$4:$E$360,$A12,FeeDetail!$C$4:$C$360,G$11) -> -9209.44 | H12: =SUM(B12:G12) -> -12133.63
A13: Interchange Charges | B13: =SUMIFS(FeeDetail!$F$4:$F$360,FeeDetail!$E$4:$E$360,$A13,FeeDetail!$C$4:$C$360,B$11) -> -77822.77 | C13: =SUMIFS(FeeDetail!$F$4:$F$360,FeeDetail!$E$4:$E$360,$A13,FeeDetail!$C$4:$C$360,C$11) -> -61395.78 | D13: =SUMIFS(FeeDetail!$F$4:$F$360,FeeDetail!$E$4:$E$360,$A13,FeeDetail!$C$4:$C$360,D$11) -> 0 | E13: =SUMIFS(FeeDetail!$F$4:$F$360,FeeDetail!$E$4:$E$360,$A13,FeeDetail!$C$4:$C$360,E$11) -> -3351.3 | F13: =SUMIFS(FeeDetail!$F$4:$F$360,FeeDetail!$E$4:$E$360,$A13,FeeDetail!$C$4:$C$360,F$11) -> -3863.23 | G13: =SUMIFS(FeeDetail!$F$4:$F$360,FeeDetail!$E$4:$E$360,$A13,FeeDetail!$C$4:$C$360,G$11) -> -3.72 | H13: =SUM(B13:G13) -> -146436.8
A14: Service Charges | B14: =SUMIFS(FeeDetail!$F$4:$F$360,FeeDetail!$E$4:$E$360,$A14,FeeDetail!$C$4:$C$360,B$11) -> -6462.97 | C14: =SUMIFS(FeeDetail!$F$4:$F$360,FeeDetail!$E$4:$E$360,$A14,FeeDetail!$C$4:$C$360,C$11) -> -4125.83 | D14: =SUMIFS(FeeDetail!$F$4:$F$360,FeeDetail!$E$4:$E$360,$A14,FeeDetail!$C$4:$C$360,D$11) -> 0 | E14: =SUMIFS(FeeDetail!$F$4:$F$360,FeeDetail!$E$4:$E$360,$A14,FeeDetail!$C$4:$C$360,E$11) -> -231.66 | F14: =SUMIFS(FeeDetail!$F$4:$F$360,FeeDetail!$E$4:$E$360,$A14,FeeDetail!$C$4:$C$360,F$11) -> -32.13 | G14: =SUMIFS(FeeDetail!$F$4:$F$360,FeeDetail!$E$4:$E$360,$A14,FeeDetail!$C$4:$C$360,G$11) -> -835.02 | H14: =SUM(B14:G14) -> -11687.61
A15: Total | B15: =SUM(B12:B14) -> -86045.46 | C15: =SUM(C12:C14) -> -66487.73 | D15: =SUM(D12:D14) -> -170 | E15: =SUM(E12:E14) -> -3608.57 | F15: =SUM(F12:F14) -> -3898.1 | G15: =SUM(G12:G14) -> -10048.18 | H15: =SUM(H12:H14) -> -170258.04
A17: Difference (computed - printed)
A18: Fees | B18: =ROUND(B12-B5,2) -> 0 | C18: =ROUND(C12-C5,2) -> 0 | D18: =ROUND(D12-D5,2) -> 0 | E18: =ROUND(E12-E5,2) -> 0 | F18: =ROUND(F12-F5,2) -> 0 | G18: =ROUND(G12-G5,2) -> 0 | H18: =ROUND(H12-H5,2) -> 0
A19: Interchange Charges | B19: =ROUND(B13-B6,2) -> 0 | C19: =ROUND(C13-C6,2) -> 0 | D19: =ROUND(D13-D6,2) -> 0 | E19: =ROUND(E13-E6,2) -> 0 | F19: =ROUND(F13-F6,2) -> 0 | G19: =ROUND(G13-G6,2) -> 0 | H19: =ROUND(H13-H6,2) -> 0
A20: Service Charges | B20: =ROUND(B14-B7,2) -> 0 | C20: =ROUND(C14-C7,2) -> 0 | D20: =ROUND(D14-D7,2) -> 0 | E20: =ROUND(E14-E7,2) -> 0 | F20: =ROUND(F14-F7,2) -> 0 | G20: =ROUND(G14-G7,2) -> 0 | H20: =ROUND(H14-H7,2) -> 0
A21: Total | B21: =ROUND(B15-B8,2) -> 0 | C21: =ROUND(C15-C8,2) -> 0 | D21: =ROUND(D15-D8,2) -> 0 | E21: =ROUND(E15-E8,2) -> 0 | F21: =ROUND(F15-F8,2) -> 0 | G21: =ROUND(G15-G8,2) -> 0 | H21: =ROUND(H15-H8,2) -> 0
A23: Category subtotals
A24: Category | B24: Statement subtotal | C24: Computed | D24: Difference
A25: Account Fees | B25: -9375.7 | C25: =SUMIFS(FeeDetail!$F$4:$F$360,FeeDetail!$B$4:$B$360,A25) -> -9375.7 | D25: =ROUND(C25-B25,2) -> 0
A26: Debit Fees | B26: -3863.23 | C26: =SUMIFS(FeeDetail!$F$4:$F$360,FeeDetail!$B$4:$B$360,A26) -> -3863.23 | D26: =ROUND(C26-B26,2) -> 0
A27: Debit Network Fees | B27: -4.9 | C27: =SUMIFS(FeeDetail!$F$4:$F$360,FeeDetail!$B$4:$B$360,A27) -> -4.9 | D27: =ROUND(C27-B27,2) -> 0
A28: Transaction Fees | B28: -157014.21 | C28: =SUMIFS(FeeDetail!$F$4:$F$360,FeeDetail!$B$4:$B$360,A28) -> -157014.21 | D28: =ROUND(C28-B28,2) -> 0
A29: Total | B29: =SUM(B25:B28) -> -170258.04 | C29: =SUM(C25:C28) -> -170258.04 | D29: =ROUND(C29-B29,2) -> 0
A31: Fee Summary (page 4)
A32: Component | B32: Statement | C32: Computed from FeeDetail | D32: Difference
A33: Fees | B33: -12133.63 | C33: =SUMIFS(FeeDetail!$F$4:$F$360,FeeDetail!$E$4:$E$360,"Fees") -> -12133.63 | D33: =ROUND(C33-B33,2) -> 0
A34: IC/PF (interchange / program fees) | B34: -146436.8 | C34: =SUMIFS(FeeDetail!$F$4:$F$360,FeeDetail!$E$4:$E$360,"Interchange Charges") -> -146436.8 | D34: =ROUND(C34-B34,2) -> 0
A35: Service Charges | B35: -11687.61 | C35: =SUMIFS(FeeDetail!$F$4:$F$360,FeeDetail!$E$4:$E$360,"Service Charges") -> -11687.61 | D35: =ROUND(C35-B35,2) -> 0
A36: Total fees | B36: -170258.04 | C36: =SUM(C33:C35) -> -170258.04 | D36: =ROUND(C36-B36,2) -> 0
A38: Why IC/PF (page 4) differs from the interchange table total
A39: Interchange table grand total (Interchange sheet) | B39: =Interchange!D152 -> -132608.12
A40: + Assessments and network fees typed "Interchange Charges" | B40: =SUMIFS(FeeDetail!$F$4:$F$360,FeeDetail!$M$4:$M$360,"Y") -> -9965.45
A41: + Debit interchange (fee list only; the interchange table shows $0.00 for all debit networks) | B41: =SUMIFS(FeeDetail!$F$4:$F$360,FeeDetail!$B$4:$B$360,"Debit Fees") -> -3863.23
A42: Reconstructed IC/PF (sum of the three lines) | B42: =SUM(B39:B41) -> -146436.8
A43: IC/PF printed on the Fee Summary | B43: =B34 -> -146436.8
A44: Difference | B44: =ROUND(B42-B43,2) -> 0
A46: Per brand: interchange table + assessments = fee matrix Interchange row
A47: Brand | B47: Interchange table | C47: Assessments in fee list | D47: Reconstructed | E47: Fee matrix (printed) | F47: Difference
...

Sheet FeeDetail
A1: Fee detail (all 357 lines)
A2: Category and Product are printed only on the first row of each group; they are forward-filled here. Recomputed = -(basis x rate) where the description states both.
A3: # | B3: Category | C3: Product | D3: Description | E3: Type | F3: Amount | G3: Basis type | H3: Basis value | I3: Rate | J3: Recomputed | K3: Variance | L3: Note | M3: Typed as Interchange but is an assessment / network fee
A4: 1 | B4: Account Fees | C4: Miscellaneous | D4: MC MONTHLY LOCATION FEE | E4: Fees | F4: -27.5
A5: 2 | B5: Account Fees | C5: Miscellaneous | D5: VISA INTL SERVICE FEE - BASE 0 TRANS TOTALING $7.15 | E5: Fees | F5: -0.07
A6: 3 | B6: Account Fees | C6: Miscellaneous | D6: ILK-COMMERCIAL SOLUTIONS FEE $411.57 AT .000100 | E6: Fees | F6: -0.04 | G6: Sales base | H6: 411.57 | I6: 0.0001 | J6: =-ROUND(H6*I6,2) -> -0.04 | K6: =ROUND(J6-F6,2) -> 0 | L6: =IF(ABS(K6)<0.005,"OK",IF(ABS(K6)<=0.11,"Rounding / minimum fee","REVIEW")) -> OK
A7: 4 | B7: Account Fees | C7: Miscellaneous | D7: ILK-COMMERCIAL SOLUTIONS FEE $410.67 AT .000100 | E7: Fees | F7: -0.04 | G7: Sales base | H7: 410.67 | I7: 0.0001 | J7: =-ROUND(H7*I7,2) -> -0.04 | K7: =ROUND(J7-F7,2) -> 0 | L7: =IF(ABS(K7)<0.005,"OK",IF(ABS(K7)<=0.11,"Rounding / minimum fee","REVIEW")) -> OK
A8: 5 | B8: Account Fees | C8: Miscellaneous | D8: REGULATORY PRODUCT FEE | E8: Fees | F8: -343.85
A9: 6 | B9: Account Fees | C9: Miscellaneous | D9: ILK-COMMERCIAL SOLUTIONS FEE $1,240.97 AT .000100 | E9: Fees | F9: -0.12 | G9: Sales base | H9: 1240.97 | I9: 0.0001 | J9: =-ROUND(H9*I9,2) -> -0.12 | K9: =ROUND(J9-F9,2) -> 0 | L9: =IF(ABS(K9)<0.005,"OK",IF(ABS(K9)<=0.11,"Rounding / minimum fee","REVIEW")) -> OK
A10: 7 | B10: Account Fees | C10: Miscellaneous | D10: ANNUAL COMPLIANCE SVC FEE | E10: Fees | F10: -6899.77
A11: 8 | B11: Account Fees | C11: Miscellaneous | D11: VS INTL ACQUIRER FEE 0 TRANS TOTALING $7.15 | E11: Fees | F11: -0.03
A12: 9 | B12: Account Fees | C12: Miscellaneous | D12: MC GLOBAL ACQUIRER FEE 0 TRANS TOTALING $985.40 | E12: Fees | F12: -8.38
A13: 10 | B13: Account Fees | C13: Miscellaneous | D13: INCOMING CHARGEBACKS ALL 1 TRANSACTIONS AT 35 | E13: Fees | F13: -35 | G13: Transactions | H13: 1 | I13: 35 | J13: =-ROUND(H13*I13,2) -> -35 | K13: =ROUND(J13-F13,2) -> 0 | L13: =IF(ABS(K13)<0.005,"OK",IF(ABS(K13)<=0.11,"Rounding / minimum fee","REVIEW")) -> OK
A14: 11 | B14: Account Fees | C14: Miscellaneous | D14: ACCOUNT MINIMUM FEE 25.00 MINIMUM LEVEL LESS 0.00 | E14: Fees | F14: -25
A15: 12 | B15: Account Fees | C15: Miscellaneous | D15: ILK-COMMERCIAL SOLUTIONS FEE $209.79 AT .000100 | E15: Fees | F15: -0.02 | G15: Sales base | H15: 209.79 | I15: 0.0001 | J15: =-ROUND(H15*I15,2) -> -0.02 | K15: =ROUND(J15-F15,2) -> 0 | L15: =IF(ABS(K15)<0.005,"OK",IF(ABS(K15)<=0.11,"Rounding / minimum fee","REVIEW")) -> OK
A16: 13 | B16: Account Fees | C16: Miscellaneous | D16: ILK-COMMERCIAL SOLUTIONS FEE $1,108.95 AT .000100 | E16: Fees | F16: -0.11 | G16: Sales base | H16: 1108.95 | I16: 0.0001 | J16: =-ROUND(H16*I16,2) -> -0.11 | K16: =ROUND(J16-F16,2) -> 0 | L16: =IF(ABS(K16)<0.005,"OK",IF(ABS(K16)<=0.11,"Rounding / minimum fee","REVIEW")) -> OK
A17: 14 | B17: Account Fees | C17: Miscellaneous | D17: US CROSS BORDER FEE 0 TRANS TOTALING $985.40 | E17: Fees | F17: -5.91
A18: 15 | B18: Account Fees | C18: Miscellaneous | D18: VISA NETWORK FEE CP 1B-08 | E18: Fees | F18: -88
A19: 16 | B19: Account Fees | C19: Miscellaneous | D19: ILK-COMMERCIAL SOLUTIONS FEE $483.68 AT .000100 | E19: Fees | F19: -0.05 | G19: Sales base | H19: 483.68 | I19: 0.0001 | J19: =-ROUND(H19*I19,2) -> -0.05 | K19: =ROUND(J19-F19,2) -> 0 | L19: =IF(ABS(K19)<0.005,"OK",IF(ABS(K19)<=0.11,"Rounding / minimum fee","REVIEW")) -> OK
A20: 17 | B20: Account Fees | C20: Miscellaneous | D20: VISA CB/EXCPT PACKAGE MAIL 1 TRANSACTIONS AT 0.78 | E20: Fees | F20: -0.78 | G20: Transactions | H20: 1 | I20: 0.78 | J20: =-ROUND(H20*I20,2) -> -0.78 | K20: =ROUND(J20-F20,2) -> 0 | L20: =IF(ABS(K20)<0.005,"OK",IF(ABS(K20)<=0.11,"Rounding / minimum fee","REVIEW")) -> OK
A21: 18 | B21: Account Fees | C21: Miscellaneous | D21: VISA NETWORK FEE CNP 2-09 | E21: Fees | F21: -1000.01
A22: 19 | B22: Account Fees | C22: Mastercard | D22: MC-MOTO DOMESTIC FEE $25,506.68 AT .000150 | E22: Fees | F22: -3.83 | G22: Sales base | H22: 25506.68 | I22: 0.00015 | J22: =-ROUND(H22*I22,2) -> -3.83 | K22: =ROUND(J22-F22,2) -> 0 | L22: =IF(ABS(K22)<0.005,"OK",IF(ABS(K22)<=0.11,"Rounding / minimum fee","REVIEW")) -> OK
A23: 20 | B23: Account Fees | C23: Mastercard | D23: MC-MOTO DOMESTIC FEE $66,812.23 AT .000150 | E23: Fees | F23: -10.02 | G23: Sales base | H23: 66812.23 | I23: 0.00015 | J23: =-ROUND(H23*I23,2) -> -10.02 | K23: =ROUND(J23-F23,2) -> 0 | L23: =IF(ABS(K23)<0.005,"OK",IF(ABS(K23)<=0.11,"Rounding / minimum fee","REVIEW")) -> OK
A24: 21 | B24: Account Fees | C24: Mastercard | D24: MC-MOTO DOMESTIC FEE $86,963.63 AT .000150 | E24: Fees | F24: -13.04 | G24: Sales base | H24: 86963.63 | I24: 0.00015 | J24: =-ROUND(H24*I24,2) -> -13.04 | K24: =ROUND(J24-F24,2) -> 0 | L24: =IF(ABS(K24)<0.005,"OK",IF(ABS(K24)<=0.11,"Rounding / minimum fee","REVIEW")) -> OK
A25: 22 | B25: Account Fees | C25: Mastercard | D25: MC-MOTO DOMESTIC FEE $49,052.79 AT .000150 | E25: Fees | F25: -7.36 | G25: Sales base | H25: 49052.79 | I25: 0.00015 | J25: =-ROUND(H25*I25,2) -> -7.36 | K25: =ROUND(J25-F25,2) -> 0 | L25: =IF(ABS(K25)<0.005,"OK",IF(ABS(K25)<=0.11,"Rounding / minimum fee","REVIEW")) -> OK
A26: 23 | B26: Account Fees | C26: Mastercard | D26: MC-MOTO DOMESTIC FEE DECLINE $26,812.10 AT .000150 | E26: Fees | F26: -4.02 | G26: Sales base | H26: 26812.1 | I26: 0.00015 | J26: =-ROUND(H26*I26,2) -> -4.02 | K26: =ROUND(J26-F26,2) -> 0 | L26: =IF(ABS(K26)<0.005,"OK",IF(ABS(K26)<=0.11,"Rounding / minimum fee","REVIEW")) -> OK
A27: 24 | B27: Account Fees | C27: Mastercard | D27: MC-MOTO DOMESTIC FEE DECLINE $36,156.88 AT .000150 | E27: Fees | F27: -5.42 | G27: Sales base | H27: 36156.88 | I27: 0.00015 | J27: =-ROUND(H27*I27,2) -> -5.42 | K27: =ROUND(J27-F27,2) -> 0 | L27: =IF(ABS(K27)<0.005,"OK",IF(ABS(K27)<=0.11,"Rounding / minimum fee","REVIEW")) -> OK
A28: 25 | B28: Account Fees | C28: Mastercard | D28: MC-MOTO DOMESTIC FEE $732.81 AT .000150 | E28: Fees | F28: -0.11 | G28: Sales base | H28: 732.81 | I28: 0.00015 | J28: =-ROUND(H28*I28,2) -> -0.11 | K28: =ROUND(J28-F28,2) -> 0 | L28: =IF(ABS(K28)<0.005,"OK",IF(ABS(K28)<=0.11,"Rounding / minimum fee","REVIEW")) -> OK
A29: 26 | B29: Account Fees | C29: Mastercard | D29: MC-MOTO DOMESTIC FEE $68,502.34 AT .000150 | E29: Fees | F29: -10.28 | G29: Sales base | H29: 68502.34 | I29: 0.00015 | J29: =-ROUND(H29*I29,2) -> -10.28 | K29: =ROUND(J29-F29,2) -> 0 | L29: =IF(ABS(K29)<0.005,"OK",IF(ABS(K29)<=0.11,"Rounding / minimum fee","REVIEW")) -> OK
A30: 27 | B30: Account Fees | C30: Mastercard | D30: MC-MOTO DOMESTIC FEE DECLINE $23,576.48 AT .000150 | E30: Fees | F30: -3.54 | G30: Sales base | H30: 23576.48 | I30: 0.00015 | J30: =-ROUND(H30*I30,2) -> -3.54 | K30: =ROUND(J30-F30,2) -> 0 | L30: =IF(ABS(K30)<0.005,"OK",IF(ABS(K30)<=0.11,"Rounding / minimum fee","REVIEW")) -> OK
A31: 28 | B31: Account Fees | C31: Mastercard | D31: MC-MOTO DOMESTIC FEE DECLINE $29,498.87 AT .000150 | E31: Fees | F31: -4.42 | G31: Sales base | H31: 29498.87 | I31: 0.00015 | J31: =-ROUND(H31*I31,2) -> -4.42 | K31: =ROUND(J31-F31,2) -> 0 | L31: =IF(ABS(K31)<0.005,"OK",IF(ABS(K31)<=0.11,"Rounding / minimum fee","REVIEW")) -> OK
A32: 29 | B32: Account Fees | C32: Mastercard | D32: MC-MOTO DOMESTIC FEE DECLINE $13,171.15 AT .000150 | E32: Fees | F32: -1.98 | G32: Sales base | H32: 13171.15 | I32: 0.00015 | J32: =-ROUND(H32*I32,2) -> -1.98 | K32: =ROUND(J32-F32,2) -> 0 | L32: =IF(ABS(K32)<0.005,"OK",IF(ABS(K32)<=0.11,"Rounding / minimum fee","REVIEW")) -> OK
A33: 30 | B33: Account Fees | C33: Mastercard | D33: MC-MOTO DOMESTIC FEE DECLINE $9,287.32 AT .000150 | E33: Fees | F33: -1.39 | G33: Sales base | H33: 9287.32 | I33: 0.00015 | J33: =-ROUND(H33*I33,2) -> -1.39 | K33: =ROUND(J33-F33,2) -> 0 | L33: =IF(ABS(K33)<0.005,"OK",IF(ABS(K33)<=0.11,"Rounding / minimum fee","REVIEW")) -> OK
... A99: 96 | B99: Account Fees | C99: Visa | D99: VI-COMMERCIAL SOLUTIONS FEE .000100 TIMES $83,808.24 | E99: Fees | F99: -8.38 | G99: Sales base | H99: 83808.24 | I99: 0.0001 | J99: =-ROUND(H99*I99,2) -> -8.38 | K99: =ROUND(J99-F99,2) -> 0 | L99: =IF(ABS(K99)<0.005,"OK",IF(ABS(K99)<=0.11,"Rounding / minimum fee","REVIEW")) -> OK
A100: 97 | B100: Debit Fees | C100: Debit | D100: MAESTRO | E100: Interchange Charges | F100: -588.32
A101: 98 | B101: Debit Fees | C101: Debit | D101: ACCEL ADVANTAGE REG | E101: Interchange Charges | F101: -1340.12
A102: 99 | B102: Debit Fees | C102: Debit | D102: MAESTRO REG DECLINE | E102: Interchange Charges | F102: -0.16
A103: 100 | B103: Debit Fees | C103: Debit | D103: MAESTRO DECLINE | E103: Interchange Charges | F103: -0.03
A104: 101 | B104: Debit Fees | C104: Debit | D104: ACCEL DECLINE | E104: Interchange Charges | F104: -0.1
A105: 102 | B105: Debit Fees | C105: Debit | D105: PAVD DECLINE | E105: Interchange Charges | F105: -0.11
...

Sheet Interchange
A1: Interchange Charges / Program Fees
A2: Recomputed = -(sales x rate + transactions x per-transaction fee). The printed rate is rounded to 4 decimals, so differences up to $0.05 are rounding.
A3: Brand | B3: Product Description | C3: Sales Total | D3: % of Sales | E3: Total No. of Transactions | F3: % of Transactions | G3: Transaction Rate | H3: Per-transaction fee | I3: Interchange / Program Charges | J3: Recomputed | K3: Variance | L3: Flag | M3: % of sales recomputed (absolute basis) | N3: % of transactions recomputed | O3: % columns check
A4: MASTERCARD | B4: MC-INT CON RTE 2 CP PREM | C4: 118.73 | D4: 0 | E4: 1 | F4: 0 | G4: 0.0185 | H4: 0 | I4: -2.2 | J4: =-ROUND(C4*G4+E4*H4,2) -> -2.2 | K4: =ROUND(J4-I4,2) -> 0 | L4: =IF(ABS(K4)<0.005,"OK",IF(ABS(K4)<=0.05,"Rounding","REVIEW")) -> OK | M4: =ABS(C4)/SUMPRODUCT(($A$4:$A$143=A4)*ABS($C$4:$C$143)) -> 4.3210678e-05 | N4: =E4/SUMIFS($E$4:$E$143,$A$4:$A$143,A4) -> 0.00030459945 | O4: =IF(AND(ABS(ROUND(M4,2)-D4)<0.0051,ABS(ROUND(N4,2)-F4)<0.0051),"OK","REVIEW") -> OK
A5: MASTERCARD | B5: MC-BUS LEVEL 5 DATA RATE II | C5: 444995.75 | D5: 0.16 | E5: 566 | F5: 0.17 | G5: 0.0225 | H5: 0.1 | I5: -10069.01 | J5: =-ROUND(C5*G5+E5*H5,2) -> -10069 | K5: =ROUND(J5-I5,2) -> 0.01 | L5: =IF(ABS(K5)<0.005,"OK",IF(ABS(K5)<=0.05,"Rounding","REVIEW")) -> Rounding | M5: =ABS(C5)/SUMPRODUCT(($A$4:$A$143=A5)*ABS($C$4:$C$143)) -> 0.16195206 | N5: =E5/SUMIFS($E$4:$E$143,$A$4:$A$143,A5) -> 0.17240329 | O5: =IF(AND(ABS(ROUND(M5,2)-D5)<0.0051,ABS(ROUND(N5,2)-F5)<0.0051),"OK","REVIEW") -> OK
A6: MASTERCARD | B6: MC-CONSUMER REFUND 1 (DB) | C6: -2363.25 | D6: 0 | E6: 14 | F6: 0 | G6: 0 | H6: 0 | I6: 0 | J6: 0 | K6: =ROUND(J6-I6,2) -> 0 | L6: =IF(ABS(K6)<0.005,"OK",IF(ABS(K6)<=0.05,"Rounding","REVIEW")) -> OK | M6: =ABS(C6)/SUMPRODUCT(($A$4:$A$143=A6)*ABS($C$4:$C$143)) -> 0.00086008283 | N6: =E6/SUMIFS($E$4:$E$143,$A$4:$A$143,A6) -> 0.0042643923 | O6: =IF(AND(ABS(ROUND(M6,2)-D6)<0.0051,ABS(ROUND(N6,2)-F6)<0.0051),"OK","REVIEW") -> OK
A7: MASTERCARD | B7: MC-US STP B2B VIP 9 | C7: 31954.35 | D7: 0.01 | E7: 14 | F7: 0 | G7: 0.0295 | H7: 0.1 | I7: -944.05 | J7: =-ROUND(C7*G7+E7*H7,2) -> -944.05 | K7: =ROUND(J7-I7,2) -> 0 | L7: =IF(ABS(K7)<0.005,"OK",IF(ABS(K7)<=0.05,"Rounding","REVIEW")) -> OK | M7: =ABS(C7)/SUMPRODUCT(($A$4:$A$143=A7)*ABS($C$4:$C$143)) -> 0.011629488 | N7: =E7/SUMIFS($E$4:$E$143,$A$4:$A$143,A7) -> 0.0042643923 | O7: =IF(AND(ABS(ROUND(M7,2)-D7)<0.0051,ABS(ROUND(N7,2)-F7)<0.0051),"OK","REVIEW") -> OK
A8: MASTERCARD | B8: MC-WRLD ELITE SMALL TICKET CP | C8: 3.99 | D8: 0 | E8: 1 | F8: 0 | G8: 0.023 | H8: 0.02 | I8: -0.11 | J8: =-ROUND(C8*G8+E8*H8,2) -> -0.11 | K8: =ROUND(J8-I8,2) -> 0 | L8: =IF(ABS(K8)<0.005,"OK",IF(ABS(K8)<=0.05,"Rounding","REVIEW")) -> OK | M8: =ABS(C8)/SUMPRODUCT(($A$4:$A$143=A8)*ABS($C$4:$C$143)) -> 1.4521233e-06 | N8: =E8/SUMIFS($E$4:$E$143,$A$4:$A$143,A8) -> 0.00030459945 | O8: =IF(AND(ABS(ROUND(M8,2)-D8)<0.0051,ABS(ROUND(N8,2)-F8)<0.0051),"OK","REVIEW") -> OK
A9: MASTERCARD | B9: MC-CORP DATA RATE I (US) BUS | C9: 67263.59 | D9: 0.02 | E9: 48 | F9: 0.01 | G9: 0.0265 | H9: 0.1 | I9: -1787.29 | J9: =-ROUND(C9*G9+E9*H9,2) -> -1787.29 | K9: =ROUND(J9-I9,2) -> 0 | L9: =IF(ABS(K9)<0.005,"OK",IF(ABS(K9)<=0.05,"Rounding","REVIEW")) -> OK | M9: =ABS(C9)/SUMPRODUCT(($A$4:$A$143=A9)*ABS($C$4:$C$143)) -> 0.024479957 | N9: =E9/SUMIFS($E$4:$E$143,$A$4:$A$143,A9) -> 0.014620774 | O9: =IF(AND(ABS(ROUND(M9,2)-D9)<0.0051,ABS(ROUND(N9,2)-F9)<0.0051),"OK","REVIEW") -> OK
A10: MASTERCARD | B10: MC-BUS LEVEL 5 DATA RATE I | C10: 237202.26 | D10: 0.09 | E10: 89 | F10: 0.03 | G10: 0.03 | H10: 0.1 | I10: -7124.97 | J10: =-ROUND(C10*G10+E10*H10,2) -> -7124.97 | K10: =ROUND(J10-I10,2) -> 0 | L10: =IF(ABS(K10)<0.005,"OK",IF(ABS(K10)<=0.05,"Rounding","REVIEW")) -> OK | M10: =ABS(C10)/SUMPRODUCT(($A$4:$A$143=A10)*ABS($C$4:$C$143)) -> 0.086327554 | N10: =E10/SUMIFS($E$4:$E$143,$A$4:$A$143,A10) -> 0.027109351 | O10: =IF(AND(ABS(ROUND(M10,2)-D10)<0.0051,ABS(ROUND(N10,2)-F10)<0.0051),"OK","REVIEW") -> OK
A11: MASTERCARD | B11: MC-CORPORATE CREDIT REFUND 3 | C11: -33828.89 | D11: 0.01 | E11: 68 | F11: 0.02 | G11: 0 | H11: 0 | I11: 0 | J11: 0 | K11: =ROUND(J11-I11,2) -> 0 | L11: =IF(ABS(K11)<0.005,"OK",IF(ABS(K11)<=0.05,"Rounding","REVIEW")) -> OK | M11: =ABS(C11)/SUMPRODUCT(($A$4:$A$143=A11)*ABS($C$4:$C$143)) -> 0.01231171 | N11: =E11/SUMIFS($E$4:$E$143,$A$4:$A$143,A11) -> 0.020712763 | O11: =IF(AND(ABS(ROUND(M11,2)-D11)<0.0051,ABS(ROUND(N11,2)-F11)<0.0051),"OK","REVIEW") -> OK
